Workbook

Sheet Pentametric Cycle
A1: n | B1: m = 4n² mod 10 | C1: C(m) = (26m − 5m²)/24 | D1: s(n)² = (n² + 4C(m))/5 | E1: s(n)² mod 10 | F1: 2 × s(n)² | G1: 2s(n)² mod 10 | H1: G / 2 | I1: Interval | J1: Greek Name | K1: Mirror Check | L1: Legend | M1: Meaning
A2: 0 | B2: =MOD(4*A2^2,10) -> 0 | C2: =(26*B2-5*B2^2)/24 -> 0 | D2: =(A2^2+4*C2)/5 -> 0 | E2: =MOD(D2,10) -> 0 | F2: =2*D2 -> 0 | G2: =MOD(F2,10) -> 0 | H2: =G2/2 -> 0 | I2: =IF(H2=0,"—",IF(H2=1,"unison (1:1)",IF(H2=2,"octave (2:1)",IF(H2=3,"fifth (3:2)",IF(H2=4,"fourth (4:3)","?"))))) -> — | J2: =IF(H2=0,"—",IF(H2=1,"ὁμώνυμον",IF(H2=2,"διὰ πασῶν",IF(H2=3,"διὰ πέντε",IF(H2=4,"διὰ τεσσάρων","?"))))) -> — | K2: {=IF(H2=INDEX($H$2:$H$53,52-ROW()+2),"✓","—")} -> — | L2: =B1 -> m = 4n² mod 10 | M2: the residue
A3: =A2+1 -> 1 | B3: =MOD(4*A3^2,10) -> 4 | C3: =(26*B3-5*B3^2)/24 -> 1 | D3: =(A3^2+4*C3)/5 -> 1 | E3: =MOD(D3,10) -> 1 | F3: =2*D3 -> 2 | G3: =MOD(F3,10) -> 2 | H3: =G3/2 -> 1 | I3: =IF(H3=0,"—",IF(H3=1,"unison (1:1)",IF(H3=2,"octave (2:1)",IF(H3=3,"fifth (3:2)",IF(H3=4,"fourth (4:3)","?"))))) -> unison (1:1) | J3: =IF(H3=0,"—",IF(H3=1,"ὁμώνυμον",IF(H3=2,"διὰ πασῶν",IF(H3=3,"διὰ πέντε",IF(H3=4,"διὰ τεσσάρων","?"))))) -> ὁμώνυμον | K3: {=IF(H3=INDEX($H$2:$H$52,51-ROW()+2),"✓","—")} -> ✓ | L3: =C1 -> C(m) = (26m − 5m²)/24 | M3: the Interval Map output
A4: =A3+1 -> 2 | B4: =MOD(4*A4^2,10) -> 6 | C4: =(26*B4-5*B4^2)/24 -> -1 | D4: =(A4^2+4*C4)/5 -> 0 | E4: =MOD(D4,10) -> 0 | F4: =2*D4 -> 0 | G4: =MOD(F4,10) -> 0 | H4: =G4/2 -> 0 | I4: =IF(H4=0,"—",IF(H4=1,"unison (1:1)",IF(H4=2,"octave (2:1)",IF(H4=3,"fifth (3:2)",IF(H4=4,"fourth (4:3)","?"))))) -> — | J4: =IF(H4=0,"—",IF(H4=1,"ὁμώνυμον",IF(H4=2,"διὰ πασῶν",IF(H4=3,"διὰ πέντε",IF(H4=4,"διὰ τεσσάρων","?"))))) -> — | K4: {=IF(H4=INDEX($H$2:$H$52,51-ROW()+2),"✓","—")} -> ✓ | L4: =D1 -> s(n)² = (n² + 4C(m))/5 | M4: the Pentametric Area
A5: =A4+1 -> 3 | B5: =MOD(4*A5^2,10) -> 6 | C5: =(26*B5-5*B5^2)/24 -> -1 | D5: =(A5^2+4*C5)/5 -> 1 | E5: =MOD(D5,10) -> 1 | F5: =2*D5 -> 2 | G5: =MOD(F5,10) -> 2 | H5: =G5/2 -> 1 | I5: =IF(H5=0,"—",IF(H5=1,"unison (1:1)",IF(H5=2,"octave (2:1)",IF(H5=3,"fifth (3:2)",IF(H5=4,"fourth (4:3)","?"))))) -> unison (1:1) | J5: =IF(H5=0,"—",IF(H5=1,"ὁμώνυμον",IF(H5=2,"διὰ πασῶν",IF(H5=3,"διὰ πέντε",IF(H5=4,"διὰ τεσσάρων","?"))))) -> ὁμώνυμον | K5: {=IF(H5=INDEX($H$2:$H$52,51-ROW()+2),"✓","—")} -> ✓ | L5: s(n)² mod 10 | M5: area last digit (original cycle)
A6: =A5+1 -> 4 | B6: =MOD(4*A6^2,10) -> 4 | C6: =(26*B6-5*B6^2)/24 -> 1 | D6: =(A6^2+4*C6)/5 -> 4 | E6: =MOD(D6,10) -> 4 | F6: =2*D6 -> 8 | G6: =MOD(F6,10) -> 8 | H6: =G6/2 -> 4 | I6: =IF(H6=0,"—",IF(H6=1,"unison (1:1)",IF(H6=2,"octave (2:1)",IF(H6=3,"fifth (3:2)",IF(H6=4,"fourth (4:3)","?"))))) -> fourth (4:3) | J6: =IF(H6=0,"—",IF(H6=1,"ὁμώνυμον",IF(H6=2,"διὰ πασῶν",IF(H6=3,"διὰ πέντε",IF(H6=4,"διὰ τεσσάρων","?"))))) -> διὰ τεσσάρων | K6: {=IF(H6=INDEX($H$2:$H$52,51-ROW()+2),"✓","—")} -> ✓ | L6: =F1 -> 2 × s(n)² | M6: the doubled area
A7: =A6+1 -> 5 | B7: =MOD(4*A7^2,10) -> 0 | C7: =(26*B7-5*B7^2)/24 -> 0 | D7: =(A7^2+4*C7)/5 -> 5 | E7: =MOD(D7,10) -> 5 | F7: =2*D7 -> 10 | G7: =MOD(F7,10) -> 0 | H7: =G7/2 -> 0 | I7: =IF(H7=0,"—",IF(H7=1,"unison (1:1)",IF(H7=2,"octave (2:1)",IF(H7=3,"fifth (3:2)",IF(H7=4,"fourth (4:3)","?"))))) -> — | J7: =IF(H7=0,"—",IF(H7=1,"ὁμώνυμον",IF(H7=2,"διὰ πασῶν",IF(H7=3,"διὰ πέντε",IF(H7=4,"διὰ τεσσάρων","?"))))) -> — | K7: {=IF(H7=INDEX($H$2:$H$52,51-ROW()+2),"✓","—")} -> ✓ | L7: =G1 -> 2s(n)² mod 10 | M7: doubled area last digit
A8: =A7+1 -> 6 | B8: =MOD(4*A8^2,10) -> 4 | C8: =(26*B8-5*B8^2)/24 -> 1 | D8: =(A8^2+4*C8)/5 -> 8 | E8: =MOD(D8,10) -> 8 | F8: =2*D8 -> 16 | G8: =MOD(F8,10) -> 6 | H8: =G8/2 -> 3 | I8: =IF(H8=0,"—",IF(H8=1,"unison (1:1)",IF(H8=2,"octave (2:1)",IF(H8=3,"fifth (3:2)",IF(H8=4,"fourth (4:3)","?"))))) -> fifth (3:2) | J8: =IF(H8=0,"—",IF(H8=1,"ὁμώνυμον",IF(H8=2,"διὰ πασῶν",IF(H8=3,"διὰ πέντε",IF(H8=4,"διὰ τεσσάρων","?"))))) -> διὰ πέντε | K8: {=IF(H8=INDEX($H$2:$H$52,51-ROW()+2),"✓","—")} -> ✓ | L8: =H1 -> G / 2 | M8: the halved digit (0–4)
A9: =A8+1 -> 7 | B9: =MOD(4*A9^2,10) -> 6 | C9: =(26*B9-5*B9^2)/24 -> -1 | D9: =(A9^2+4*C9)/5 -> 9 | E9: =MOD(D9,10) -> 9 | F9: =2*D9 -> 18 | G9: =MOD(F9,10) -> 8 | H9: =G9/2 -> 4 | I9: =IF(H9=0,"—",IF(H9=1,"unison (1:1)",IF(H9=2,"octave (2:1)",IF(H9=3,"fifth (3:2)",IF(H9=4,"fourth (4:3)","?"))))) -> fourth (4:3) | J9: =IF(H9=0,"—",IF(H9=1,"ὁμώνυμον",IF(H9=2,"διὰ πασῶν",IF(H9=3,"διὰ πέντε",IF(H9=4,"διὰ τεσσάρων","?"))))) -> διὰ τεσσάρων | K9: {=IF(H9=INDEX($H$2:$H$52,51-ROW()+2),"✓","—")} -> ✓ | L9: =I1 -> Interval | M9: name of the interval
A10: =A9+1 -> 8 | B10: =MOD(4*A10^2,10) -> 6 | C10: =(26*B10-5*B10^2)/24 -> -1 | D10: =(A10^2+4*C10)/5 -> 12 | E10: =MOD(D10,10) -> 2 | F10: =2*D10 -> 24 | G10: =MOD(F10,10) -> 4 | H10: =G10/2 -> 2 | I10: =IF(H10=0,"—",IF(H10=1,"unison (1:1)",IF(H10=2,"octave (2:1)",IF(H10=3,"fifth (3:2)",IF(H10=4,"fourth (4:3)","?"))))) -> octave (2:1) | J10: =IF(H10=0,"—",IF(H10=1,"ὁμώνυμον",IF(H10=2,"διὰ πασῶν",IF(H10=3,"διὰ πέντε",IF(H10=4,"διὰ τεσσάρων","?"))))) -> διὰ πασῶν | K10: {=IF(H10=INDEX($H$2:$H$52,51-ROW()+2),"✓","—")} -> ✓ | L10: =J1 -> Greek Name | M10: Greek interval name
A11: =A10+1 -> 9 | B11: =MOD(4*A11^2,10) -> 4 | C11: =(26*B11-5*B11^2)/24 -> 1 | D11: =(A11^2+4*C11)/5 -> 17 | E11: =MOD(D11,10) -> 7 | F11: =2*D11 -> 34 | G11: =MOD(F11,10) -> 4 | H11: =G11/2 -> 2 | I11: =IF(H11=0,"—",IF(H11=1,"unison (1:1)",IF(H11=2,"octave (2:1)",IF(H11=3,"fifth (3:2)",IF(H11=4,"fourth (4:3)","?"))))) -> octave (2:1) | J11: =IF(H11=0,"—",IF(H11=1,"ὁμώνυμον",IF(H11=2,"διὰ πασῶν",IF(H11=3,"διὰ πέντε",IF(H11=4,"διὰ τεσσάρων","?"))))) -> διὰ πασῶν | K11: {=IF(H11=INDEX($H$2:$H$52,51-ROW()+2),"✓","—")} -> ✓ | L11: =K1 -> Mirror Check | M11: mirror verification
A12: =A11+1 -> 10 | B12: =MOD(4*A12^2,10) -> 0 | C12: =(26*B12-5*B12^2)/24 -> 0 | D12: =(A12^2+4*C12)/5 -> 20 | E12: =MOD(D12,10) -> 0 | F12: =2*D12 -> 40 | G12: =MOD(F12,10) -> 0 | H12: =G12/2 -> 0 | I12: =IF(H12=0,"—",IF(H12=1,"unison (1:1)",IF(H12=2,"octave (2:1)",IF(H12=3,"fifth (3:2)",IF(H12=4,"fourth (4:3)","?"))))) -> — | J12: =IF(H12=0,"—",IF(H12=1,"ὁμώνυμον",IF(H12=2,"διὰ πασῶν",IF(H12=3,"διὰ πέντε",IF(H12=4,"διὰ τεσσάρων","?"))))) -> — | K12: {=IF(H12=INDEX($H$2:$H$52,51-ROW()+2),"✓","—")} -> ✓
A13: =A12+1 -> 11 | B13: =MOD(4*A13^2,10) -> 4 | C13: =(26*B13-5*B13^2)/24 -> 1 | D13: =(A13^2+4*C13)/5 -> 25 | E13: =MOD(D13,10) -> 5 | F13: =2*D13 -> 50 | G13: =MOD(F13,10) -> 0 | H13: =G13/2 -> 0 | I13: =IF(H13=0,"—",IF(H13=1,"unison (1:1)",IF(H13=2,"octave (2:1)",IF(H13=3,"fifth (3:2)",IF(H13=4,"fourth (4:3)","?"))))) -> — | J13: =IF(H13=0,"—",IF(H13=1,"ὁμώνυμον",IF(H13=2,"διὰ πασῶν",IF(H13=3,"διὰ πέντε",IF(H13=4,"διὰ τεσσάρων","?"))))) -> — | K13: {=IF(H13=INDEX($H$2:$H$52,51-ROW()+2),"✓","—")} -> ✓
A14: =A13+1 -> 12 | B14: =MOD(4*A14^2,10) -> 6 | C14: =(26*B14-5*B14^2)/24 -> -1 | D14: =(A14^2+4*C14)/5 -> 28 | E14: =MOD(D14,10) -> 8 | F14: =2*D14 -> 56 | G14: =MOD(F14,10) -> 6 | H14: =G14/2 -> 3 | I14: =IF(H14=0,"—",IF(H14=1,"unison (1:1)",IF(H14=2,"octave (2:1)",IF(H14=3,"fifth (3:2)",IF(H14=4,"fourth (4:3)","?"))))) -> fifth (3:2) | J14: =IF(H14=0,"—",IF(H14=1,"ὁμώνυμον",IF(H14=2,"διὰ πασῶν",IF(H14=3,"διὰ πέντε",IF(H14=4,"διὰ τεσσάρων","?"))))) -> διὰ πέντε | K14: {=IF(H14=INDEX($H$2:$H$52,51-ROW()+2),"✓","—")} -> ✓
A15: =A14+1 -> 13 | B15: =MOD(4*A15^2,10) -> 6 | C15: =(26*B15-5*B15^2)/24 -> -1 | D15: =(A15^2+4*C15)/5 -> 33 | E15: =MOD(D15,10) -> 3 | F15: =2*D15 -> 66 | G15: =MOD(F15,10) -> 6 | H15: =G15/2 -> 3 | I15: =IF(H15=0,"—",IF(H15=1,"unison (1:1)",IF(H15=2,"octave (2:1)",IF(H15=3,"fifth (3:2)",IF(H15=4,"fourth (4:3)","?"))))) -> fifth (3:2) | J15: =IF(H15=0,"—",IF(H15=1,"ὁμώνυμον",IF(H15=2,"διὰ πασῶν",IF(H15=3,"διὰ πέντε",IF(H15=4,"διὰ τεσσάρων","?"))))) -> διὰ πέντε | K15: {=IF(H15=INDEX($H$2:$H$52,51-ROW()+2),"✓","—")} -> ✓ | L15: Structural Note
A16: =A15+1 -> 14 | B16: =MOD(4*A16^2,10) -> 4 | C16: =(26*B16-5*B16^2)/24 -> 1 | D16: =(A16^2+4*C16)/5 -> 40 | E16: =MOD(D16,10) -> 0 | F16: =2*D16 -> 80 | G16: =MOD(F16,10) -> 0 | H16: =G16/2 -> 0 | I16: =IF(H16=0,"—",IF(H16=1,"unison (1:1)",IF(H16=2,"octave (2:1)",IF(H16=3,"fifth (3:2)",IF(H16=4,"fourth (4:3)","?"))))) -> — | J16: =IF(H16=0,"—",IF(H16=1,"ὁμώνυμον",IF(H16=2,"διὰ πασῶν",IF(H16=3,"διὰ πέντε",IF(H16=4,"διὰ τεσσάρων","?"))))) -> — | K16: {=IF(H16=INDEX($H$2:$H$52,51-ROW()+2),"✓","—")} -> ✓ | L16: Vertebra: 25 terms = 5²; 24 transitions = 4!; Axis at n=25
A17: =A16+1 -> 15 | B17: =MOD(4*A17^2,10) -> 0 | C17: =(26*B17-5*B17^2)/24 -> 0 | D17: =(A17^2+4*C17)/5 -> 45 | E17: =MOD(D17,10) -> 5 | F17: =2*D17 -> 90 | G17: =MOD(F17,10) -> 0 | H17: =G17/2 -> 0 | I17: =IF(H17=0,"—",IF(H17=1,"unison (1:1)",IF(H17=2,"octave (2:1)",IF(H17=3,"fifth (3:2)",IF(H17=4,"fourth (4:3)","?"))))) -> — | J17: =IF(H17=0,"—",IF(H17=1,"ὁμώνυμον",IF(H17=2,"διὰ πασῶν",IF(H17=3,"διὰ πέντε",IF(H17=4,"διὰ τεσσάρων","?"))))) -> — | K17: {=IF(H17=INDEX($H$2:$H$52,51-ROW()+2),"✓","—")} -> ✓
A18: =A17+1 -> 16 | B18: =MOD(4*A18^2,10) -> 4 | C18: =(26*B18-5*B18^2)/24 -> 1 | D18: =(A18^2+4*C18)/5 -> 52 | E18: =MOD(D18,10) -> 2 | F18: =2*D18 -> 104 | G18: =MOD(F18,10) -> 4 | H18: =G18/2 -> 2 | I18: =IF(H18=0,"—",IF(H18=1,"unison (1:1)",IF(H18=2,"octave (2:1)",IF(H18=3,"fifth (3:2)",IF(H18=4,"fourth (4:3)","?"))))) -> octave (2:1) | J18: =IF(H18=0,"—",IF(H18=1,"ὁμώνυμον",IF(H18=2,"διὰ πασῶν",IF(H18=3,"διὰ πέντε",IF(H18=4,"διὰ τεσσάρων","?"))))) -> διὰ πασῶν | K18: {=IF(H18=INDEX($H$2:$H$52,51-ROW()+2),"✓","—")} -> ✓
A19: =A18+1 -> 17 | B19: =MOD(4*A19^2,10) -> 6 | C19: =(26*B19-5*B19^2)/24 -> -1 | D19: =(A19^2+4*C19)/5 -> 57 | E19: =MOD(D19,10) -> 7 | F19: =2*D19 -> 114 | G19: =MOD(F19,10) -> 4 | H19: =G19/2 -> 2 | I19: =IF(H19=0,"—",IF(H19=1,"unison (1:1)",IF(H19=2,"octave (2:1)",IF(H19=3,"fifth (3:2)",IF(H19=4,"fourth (4:3)","?"))))) -> octave (2:1) | J19: =IF(H19=0,"—",IF(H19=1,"ὁμώνυμον",IF(H19=2,"διὰ πασῶν",IF(H19=3,"διὰ πέντε",IF(H19=4,"διὰ τεσσάρων","?"))))) -> διὰ πασῶν | K19: {=IF(H19=INDEX($H$2:$H$52,51-ROW()+2),"✓","—")} -> ✓
A20: =A19+1 -> 18 | B20: =MOD(4*A20^2,10) -> 6 | C20: =(26*B20-5*B20^2)/24 -> -1 | D20: =(A20^2+4*C20)/5 -> 64 | E20: =MOD(D20,10) -> 4 | F20: =2*D20 -> 128 | G20: =MOD(F20,10) -> 8 | H20: =G20/2 -> 4 | I20: =IF(H20=0,"—",IF(H20=1,"unison (1:1)",IF(H20=2,"octave (2:1)",IF(H20=3,"fifth (3:2)",IF(H20=4,"fourth (4:3)","?"))))) -> fourth (4:3) | J20: =IF(H20=0,"—",IF(H20=1,"ὁμώνυμον",IF(H20=2,"διὰ πασῶν",IF(H20=3,"διὰ πέντε",IF(H20=4,"διὰ τεσσάρων","?"))))) -> διὰ τεσσάρων | K20: {=IF(H20=INDEX($H$2:$H$52,51-ROW()+2),"✓","—")} -> ✓
A21: =A20+1 -> 19 | B21: =MOD(4*A21^2,10) -> 4 | C21: =(26*B21-5*B21^2)/24 -> 1 | D21: =(A21^2+4*C21)/5 -> 73 | E21: =MOD(D21,10) -> 3 | F21: =2*D21 -> 146 | G21: =MOD(F21,10) -> 6 | H21: =G21/2 -> 3 | I21: =IF(H21=0,"—",IF(H21=1,"unison (1:1)",IF(H21=2,"octave (2:1)",IF(H21=3,"fifth (3:2)",IF(H21=4,"fourth (4:3)","?"))))) -> fifth (3:2) | J21: =IF(H21=0,"—",IF(H21=1,"ὁμώνυμον",IF(H21=2,"διὰ πασῶν",IF(H21=3,"διὰ πέντε",IF(H21=4,"διὰ τεσσάρων","?"))))) -> διὰ πέντε | K21: {=IF(H21=INDEX($H$2:$H$52,51-ROW()+2),"✓","—")} -> ✓
A22: =A21+1 -> 20 | B22: =MOD(4*A22^2,10) -> 0 | C22: =(26*B22-5*B22^2)/24 -> 0 | D22: =(A22^2+4*C22)/5 -> 80 | E22: =MOD(D22,10) -> 0 | F22: =2*D22 -> 160 | G22: =MOD(F22,10) -> 0 | H22: =G22/2 -> 0 | I22: =IF(H22=0,"—",IF(H22=1,"unison (1:1)",IF(H22=2,"octave (2:1)",IF(H22=3,"fifth (3:2)",IF(H22=4,"fourth (4:3)","?"))))) -> — | J22: =IF(H22=0,"—",IF(H22=1,"ὁμώνυμον",IF(H22=2,"διὰ πασῶν",IF(H22=3,"διὰ πέντε",IF(H22=4,"διὰ τεσσάρων","?"))))) -> — | K22: {=IF(H22=INDEX($H$2:$H$52,51-ROW()+2),"✓","—")} -> ✓
A23: =A22+1 -> 21 | B23: =MOD(4*A23^2,10) -> 4 | C23: =(26*B23-5*B23^2)/24 -> 1 | D23: =(A23^2+4*C23)/5 -> 89 | E23: =MOD(D23,10) -> 9 | F23: =2*D23 -> 178 | G23: =MOD(F23,10) -> 8 | H23: =G23/2 -> 4 | I23: =IF(H23=0,"—",IF(H23=1,"unison (1:1)",IF(H23=2,"octave (2:1)",IF(H23=3,"fifth (3:2)",IF(H23=4,"fourth (4:3)","?"))))) -> fourth (4:3) | J23: =IF(H23=0,"—",IF(H23=1,"ὁμώνυμον",IF(H23=2,"διὰ πασῶν",IF(H23=3,"διὰ πέντε",IF(H23=4,"διὰ τεσσάρων","?"))))) -> διὰ τεσσάρων | K23: {=IF(H23=INDEX($H$2:$H$52,51-ROW()+2),"✓","—")} -> ✓
A24: =A23+1 -> 22 | B24: =MOD(4*A24^2,10) -> 6 | C24: =(26*B24-5*B24^2)/24 -> -1 | D24: =(A24^2+4*C24)/5 -> 96 | E24: =MOD(D24,10) -> 6 | F24: =2*D24 -> 192 | G24: =MOD(F24,10) -> 2 | H24: =G24/2 -> 1 | I24: =IF(H24=0,"—",IF(H24=1,"unison (1:1)",IF(H24=2,"octave (2:1)",IF(H24=3,"fifth (3:2)",IF(H24=4,"fourth (4:3)","?"))))) -> unison (1:1) | J24: =IF(H24=0,"—",IF(H24=1,"ὁμώνυμον",IF(H24=2,"διὰ πασῶν",IF(H24=3,"διὰ πέντε",IF(H24=4,"διὰ τεσσάρων","?"))))) -> ὁμώνυμον | K24: {=IF(H24=INDEX($H$2:$H$52,51-ROW()+2),"✓","—")} -> ✓
A25: =A24+1 -> 23 | B25: =MOD(4*A25^2,10) -> 6 | C25: =(26*B25-5*B25^2)/24 -> -1 | D25: =(A25^2+4*C25)/5 -> 105 | E25: =MOD(D25,10) -> 5 | F25: =2*D25 -> 210 | G25: =MOD(F25,10) -> 0 | H25: =G25/2 -> 0 | I25: =IF(H25=0,"—",IF(H25=1,"unison (1:1)",IF(H25=2,"octave (2:1)",IF(H25=3,"fifth (3:2)",IF(H25=4,"fourth (4:3)","?"))))) -> — | J25: =IF(H25=0,"—",IF(H25=1,"ὁμώνυμον",IF(H25=2,"διὰ πασῶν",IF(H25=3,"διὰ πέντε",IF(H25=4,"διὰ τεσσάρων","?"))))) -> — | K25: {=IF(H25=INDEX($H$2:$H$52,51-ROW()+2),"✓","—")} -> ✓
A26: =A25+1 -> 24 | B26: =MOD(4*A26^2,10) -> 4 | C26: =(26*B26-5*B26^2)/24 -> 1 | D26: =(A26^2+4*C26)/5 -> 116 | E26: =MOD(D26,10) -> 6 | F26: =2*D26 -> 232 | G26: =MOD(F26,10) -> 2 | H26: =G26/2 -> 1 | I26: =IF(H26=0,"—",IF(H26=1,"unison (1:1)",IF(H26=2,"octave (2:1)",IF(H26=3,"fifth (3:2)",IF(H26=4,"fourth (4:3)","?"))))) -> unison (1:1) | J26: =IF(H26=0,"—",IF(H26=1,"ὁμώνυμον",IF(H26=2,"διὰ πασῶν",IF(H26=3,"διὰ πέντε",IF(H26=4,"διὰ τεσσάρων","?"))))) -> ὁμώνυμον | K26: {=IF(H26=INDEX($H$2:$H$52,51-ROW()+2),"✓","—")} -> ✓
A27: =A26+1 -> 25 | B27: =MOD(4*A27^2,10) -> 0 | C27: =(26*B27-5*B27^2)/24 -> 0 | D27: =(A27^2+4*C27)/5 -> 125 | E27: =MOD(D27,10) -> 5 | F27: =2*D27 -> 250 | G27: =MOD(F27,10) -> 0 | H27: =G27/2 -> 0 | I27: =IF(H27=0,"—",IF(H27=1,"unison (1:1)",IF(H27=2,"octave (2:1)",IF(H27=3,"fifth (3:2)",IF(H27=4,"fourth (4:3)","?"))))) -> — | J27: =IF(H27=0,"—",IF(H27=1,"ὁμώνυμον",IF(H27=2,"διὰ πασῶν",IF(H27=3,"διὰ πέντε",IF(H27=4,"διὰ τεσσάρων","?"))))) -> — | K27: {=IF(H27=INDEX($H$2:$H$52,51-ROW()+2),"✓","—")} -> ✓
A28: =A27+1 -> 26 | B28: =MOD(4*A28^2,10) -> 4 | C28: =(26*B28-5*B28^2)/24 -> 1 | D28: =(A28^2+4*C28)/5 -> 136 | E28: =MOD(D28,10) -> 6 | F28: =2*D28 -> 272 | G28: =MOD(F28,10) -> 2 | H28: =G28/2 -> 1 | I28: =IF(H28=0,"—",IF(H28=1,"unison (1:1)",IF(H28=2,"octave (2:1)",IF(H28=3,"fifth (3:2)",IF(H28=4,"fourth (4:3)","?"))))) -> unison (1:1) | J28: =IF(H28=0,"—",IF(H28=1,"ὁμώνυμον",IF(H28=2,"διὰ πασῶν",IF(H28=3,"διὰ πέντε",IF(H28=4,"διὰ τεσσάρων","?"))))) -> ὁμώνυμον | K28: {=IF(H28=INDEX($H$2:$H$52,51-ROW()+2),"✓","—")} -> ✓
... A52: =A51+1 -> 50 | B52: =MOD(4*A52^2,10) -> 0 | C52: =(26*B52-5*B52^2)/24 -> 0 | D52: =(A52^2+4*C52)/5 -> 500 | E52: =MOD(D52,10) -> 0 | F52: =2*D52 -> 1000 | G52: =MOD(F52,10) -> 0 | H52: =G52/2 -> 0 | I52: =IF(H52=0,"—",IF(H52=1,"unison (1:1)",IF(H52=2,"octave (2:1)",IF(H52=3,"fifth (3:2)",IF(H52=4,"fourth (4:3)","?"))))) -> — | J52: =IF(H52=0,"—",IF(H52=1,"ὁμώνυμον",IF(H52=2,"διὰ πασῶν",IF(H52=3,"διὰ πέντε",IF(H52=4,"διὰ τεσσάρων","?"))))) -> — | K52: {=IF(H52=INDEX($H$2:$H$52,51-ROW()+2),"✓","—")} -> ✓
A53: =A52+1 -> 51 | B53: =MOD(4*A53^2,10) -> 4 | C53: =(26*B53-5*B53^2)/24 -> 1 | D53: =(A53^2+4*C53)/5 -> 521 | E53: =MOD(D53,10) -> 1 | F53: =2*D53 -> 1042 | G53: =MOD(F53,10) -> 2 | H53: =G53/2 -> 1 | I53: =IF(H53=0,"—",IF(H53=1,"unison (1:1)",IF(H53=2,"octave (2:1)",IF(H53=3,"fifth (3:2)",IF(H53=4,"fourth (4:3)","?"))))) -> unison (1:1) | J53: =IF(H53=0,"—",IF(H53=1,"ὁμώνυμον",IF(H53=2,"διὰ πασῶν",IF(H53=3,"διὰ πέντε",IF(H53=4,"διὰ τεσσάρων","?"))))) -> ὁμώνυμον
A54: =A53+1 -> 52 | B54: =MOD(4*A54^2,10) -> 6 | C54: =(26*B54-5*B54^2)/24 -> -1 | D54: =(A54^2+4*C54)/5 -> 540 | E54: =MOD(D54,10) -> 0 | F54: =2*D54 -> 1080 | G54: =MOD(F54,10) -> 0 | H54: =G54/2 -> 0 | I54: =IF(H54=0,"—",IF(H54=1,"unison (1:1)",IF(H54=2,"octave (2:1)",IF(H54=3,"fifth (3:2)",IF(H54=4,"fourth (4:3)","?"))))) -> — | J54: =IF(H54=0,"—",IF(H54=1,"ὁμώνυμον",IF(H54=2,"διὰ πασῶν",IF(H54=3,"διὰ πέντε",IF(H54=4,"διὰ τεσσάρων","?"))))) -> —
A55: =A54+1 -> 53 | B55: =MOD(4*A55^2,10) -> 6 | C55: =(26*B55-5*B55^2)/24 -> -1 | D55: =(A55^2+4*C55)/5 -> 561 | E55: =MOD(D55,10) -> 1 | F55: =2*D55 -> 1122 | G55: =MOD(F55,10) -> 2 | H55: =G55/2 -> 1 | I55: =IF(H55=0,"—",IF(H55=1,"unison (1:1)",IF(H55=2,"octave (2:1)",IF(H55=3,"fifth (3:2)",IF(H55=4,"fourth (4:3)","?"))))) -> unison (1:1) | J55: =IF(H55=0,"—",IF(H55=1,"ὁμώνυμον",IF(H55=2,"διὰ πασῶν",IF(H55=3,"διὰ πέντε",IF(H55=4,"διὰ τεσσάρων","?"))))) -> ὁμώνυμον
A56: =A55+1 -> 54 | B56: =MOD(4*A56^2,10) -> 4 | C56: =(26*B56-5*B56^2)/24 -> 1 | D56: =(A56^2+4*C56)/5 -> 584 | E56: =MOD(D56,10) -> 4 | F56: =2*D56 -> 1168 | G56: =MOD(F56,10) -> 8 | H56: =G56/2 -> 4 | I56: =IF(H56=0,"—",IF(H56=1,"unison (1:1)",IF(H56=2,"octave (2:1)",IF(H56=3,"fifth (3:2)",IF(H56=4,"fourth (4:3)","?"))))) -> fourth (4:3) | J56: =IF(H56=0,"—",IF(H56=1,"ὁμώνυμον",IF(H56=2,"διὰ πασῶν",IF(H56=3,"διὰ πέντε",IF(H56=4,"διὰ τεσσάρων","?"))))) -> διὰ τεσσάρων
A57: =A56+1 -> 55 | B57: =MOD(4*A57^2,10) -> 0 | C57: =(26*B57-5*B57^2)/24 -> 0 | D57: =(A57^2+4*C57)/5 -> 605 | E57: =MOD(D57,10) -> 5 | F57: =2*D57 -> 1210 | G57: =MOD(F57,10) -> 0 | H57: =G57/2 -> 0 | I57: =IF(H57=0,"—",IF(H57=1,"unison (1:1)",IF(H57=2,"octave (2:1)",IF(H57=3,"fifth (3:2)",IF(H57=4,"fourth (4:3)","?"))))) -> — | J57: =IF(H57=0,"—",IF(H57=1,"ὁμώνυμον",IF(H57=2,"διὰ πασῶν",IF(H57=3,"διὰ πέντε",IF(H57=4,"διὰ τεσσάρων","?"))))) -> —
A58: =A57+1 -> 56 | B58: =MOD(4*A58^2,10) -> 4 | C58: =(26*B58-5*B58^2)/24 -> 1 | D58: =(A58^2+4*C58)/5 -> 628 | E58: =MOD(D58,10) -> 8 | F58: =2*D58 -> 1256 | G58: =MOD(F58,10) -> 6 | H58: =G58/2 -> 3 | I58: =IF(H58=0,"—",IF(H58=1,"unison (1:1)",IF(H58=2,"octave (2:1)",IF(H58=3,"fifth (3:2)",IF(H58=4,"fourth (4:3)","?"))))) -> fifth (3:2) | J58: =IF(H58=0,"—",IF(H58=1,"ὁμώνυμον",IF(H58=2,"διὰ πασῶν",IF(H58=3,"διὰ πέντε",IF(H58=4,"διὰ τεσσάρων","?"))))) -> διὰ πέντε
A59: =A58+1 -> 57 | B59: =MOD(4*A59^2,10) -> 6 | C59: =(26*B59-5*B59^2)/24 -> -1 | D59: =(A59^2+4*C59)/5 -> 649 | E59: =MOD(D59,10) -> 9 | F59: =2*D59 -> 1298 | G59: =MOD(F59,10) -> 8 | H59: =G59/2 -> 4 | I59: =IF(H59=0,"—",IF(H59=1,"unison (1:1)",IF(H59=2,"octave (2:1)",IF(H59=3,"fifth (3:2)",IF(H59=4,"fourth (4:3)","?"))))) -> fourth (4:3) | J59: =IF(H59=0,"—",IF(H59=1,"ὁμώνυμον",IF(H59=2,"διὰ πασῶν",IF(H59=3,"διὰ πέντε",IF(H59=4,"διὰ τεσσάρων","?"))))) -> διὰ τεσσάρων
A60: =A59+1 -> 58 | B60: =MOD(4*A60^2,10) -> 6 | C60: =(26*B60-5*B60^2)/24 -> -1 | D60: =(A60^2+4*C60)/5 -> 672 | E60: =MOD(D60,10) -> 2 | F60: =2*D60 -> 1344 | G60: =MOD(F60,10) -> 4 | H60: =G60/2 -> 2 | I60: =IF(H60=0,"—",IF(H60=1,"unison (1:1)",IF(H60=2,"octave (2:1)",IF(H60=3,"fifth (3:2)",IF(H60=4,"fourth (4:3)","?"))))) -> octave (2:1) | J60: =IF(H60=0,"—",IF(H60=1,"ὁμώνυμον",IF(H60=2,"διὰ πασῶν",IF(H60=3,"διὰ πέντε",IF(H60=4,"διὰ τεσσάρων","?"))))) -> διὰ πασῶν
A61: =A60+1 -> 59 | B61: =MOD(4*A61^2,10) -> 4 | C61: =(26*B61-5*B61^2)/24 -> 1 | D61: =(A61^2+4*C61)/5 -> 697 | E61: =MOD(D61,10) -> 7 | F61: =2*D61 -> 1394 | G61: =MOD(F61,10) -> 4 | H61: =G61/2 -> 2 | I61: =IF(H61=0,"—",IF(H61=1,"unison (1:1)",IF(H61=2,"octave (2:1)",IF(H61=3,"fifth (3:2)",IF(H61=4,"fourth (4:3)","?"))))) -> octave (2:1) | J61: =IF(H61=0,"—",IF(H61=1,"ὁμώνυμον",IF(H61=2,"διὰ πασῶν",IF(H61=3,"διὰ πέντε",IF(H61=4,"διὰ τεσσάρων","?"))))) -> διὰ πασῶν
A62: =A61+1 -> 60 | B62: =MOD(4*A62^2,10) -> 0 | C62: =(26*B62-5*B62^2)/24 -> 0 | D62: =(A62^2+4*C62)/5 -> 720 | E62: =MOD(D62,10) -> 0 | F62: =2*D62 -> 1440 | G62: =MOD(F62,10) -> 0 | H62: =G62/2 -> 0 | I62: =IF(H62=0,"—",IF(H62=1,"unison (1:1)",IF(H62=2,"octave (2:1)",IF(H62=3,"fifth (3:2)",IF(H62=4,"fourth (4:3)","?"))))) -> — | J62: =IF(H62=0,"—",IF(H62=1,"ὁμώνυμον",IF(H62=2,"διὰ πασῶν",IF(H62=3,"διὰ πέντε",IF(H62=4,"διὰ τεσσάρων","?"))))) -> —
A63: =A62+1 -> 61 | B63: =MOD(4*A63^2,10) -> 4 | C63: =(26*B63-5*B63^2)/24 -> 1 | D63: =(A63^2+4*C63)/5 -> 745 | E63: =MOD(D63,10) -> 5 | F63: =2*D63 -> 1490 | G63: =MOD(F63,10) -> 0 | H63: =G63/2 -> 0 | I63: =IF(H63=0,"—",IF(H63=1,"unison (1:1)",IF(H63=2,"octave (2:1)",IF(H63=3,"fifth (3:2)",IF(H63=4,"fourth (4:3)","?"))))) -> — | J63: =IF(H63=0,"—",IF(H63=1,"ὁμώνυμον",IF(H63=2,"διὰ πασῶν",IF(H63=3,"διὰ πέντε",IF(H63=4,"διὰ τεσσάρων","?"))))) -> —
...

Sheet Verification
A1: Interval | B1: Digit | C1: Greek name | D1: Vertebra count (25 terms) | E1: Count in Palindrome (51) | F1: Frequency
A2: Origin (silence) | B2: 0 | C2: — | D2: =COUNTIF('Pentametric Cycle'!H2:H26,B2) -> 9 | E2: =COUNTIF('Pentametric Cycle'!H2:H52,B2) -> 19 | F2: =D2/25 -> 0.36
A3: Unison (1:1) | B3: 1 | C3: ὁμώνυμον | D3: =COUNTIF('Pentametric Cycle'!H2:H26,B3) -> 4 | E3: =COUNTIF('Pentametric Cycle'!H2:H52,B3) -> 8 | F3: =D3/25 -> 0.16
A4: Octave (2:1) | B4: 2 | C4: διὰ πασῶν | D4: =COUNTIF('Pentametric Cycle'!H2:H26,B4) -> 4 | E4: =COUNTIF('Pentametric Cycle'!H2:H55,B4) -> 8 | F4: =D4/25 -> 0.16
A5: Fifth (3:2) | B5: 3 | C5: διὰ πέντε | D5: =COUNTIF('Pentametric Cycle'!H2:H26,B5) -> 4 | E5: =COUNTIF('Pentametric Cycle'!H2:H52,B5) -> 8 | F5: =D5/25 -> 0.16
A6: Fourth (4:3) | B6: 4 | C6: διὰ τεσσάρων | D6: =COUNTIF('Pentametric Cycle'!H2:H26,B6) -> 4 | E6: =COUNTIF('Pentametric Cycle'!H2:H52,B6) -> 8 | F6: =D6/25 -> 0.16
A7: TOTAL | D7: =SUM(D2:D6) -> 25 | E7: =SUM(E2:E6) -> 51 | F7: =SUM(F2:F6) -> 1
A9: Structural Note
A10: Vertebra: 25 terms = 5²
A11: Transitions: 24 = 4!
A12: Axis: 1 (n=25)
A13: Pythagorean triple: 9 + 16 = 25

Sheet Structure
A1: Structure | B1: Count | C1: Square / Factorial | D1: Greek Name | E1: English Name
A2: Terms in Vertebra | B2: 25 | C2: 5^2 | D2: Ὁ Πεντάμετρος Σπόνδυλος | E2: The Pentametric Vertebra
A3: Transitions in Vertebra | B3: 24 | C3: 4! | D3: Αἱ Εἴκοσι Τέσσαρες Μεταβάσεις | E3: The Twenty-Four Transitions
A4: Axis | B4: 1 | C4: — | D4: Ὁ Ἄξων | E4: The Axis
A5: Silence Skeleton | B5: 9 | C5: 3^2 | D5: Ἡ Τριάδικη Σιγή | E5: The Triadic Silence
A6: Consonance Skeleton | B6: 16 | C6: 4^2 | D6: Τὸ Τετράγωνον Σπέρμα | E6: The Square Seed
A7: Consonances | B7: 4 | C7: 2^2 | D7: Αἱ Τέσσαρες Συμφωνίαι | E7: The Four Consonances
A9: Structure | B9: Count | C9: Formula | D9: Greek Name | E9: English Name
A10: Palindrome | B10: 51 | C10: 2×5²+1 | D10: Ὁ Πενταμετρικὸς Παλίνδρομος | E10: The Pentametric Palindrome
A11: Part 1 | B11: 25 | C11: 5^2 | D11: — | E11: First half
A12: Axis | B12: 1 | C12: — | D12: Ὁ Ἄξων | E12: The Axis
A13: Part 2 | B13: 25 | C13: 5^2 | D13: — | E13: Second half
A15: Identity | B15: Expression | C15: Greek Name | D15: English Name
A16: Pythagorean Triple | B16: (3^2)+(4^2) = 5^2 | C16: Ἡ Πυθαγόρειος Τριάς | D16: The Pythagorean Triple
A17: Silence + Consonance | B17: 9+16=25 | C17: — | D17: Triadic Silence + Square Seed = Vertebra

Sheet Palindrome
A1: Position | B1: Digit | C1: Interval | D1: Greek Name | E1: English Name | F1: Structural Marker | G1: Visual Mirror | H1: Transitions
A2: 0 | B2: ='Pentametric Cycle'!H2 -> 0 | C2: =IF(B2=0,"—",IF(B2=1,"unison (1:1)",IF(B2=2,"octave (2:1)",IF(B2=3,"fifth (3:2)",IF(B2=4,"fourth (4:3)","?"))))) -> — | D2: =IF(B2=0,"—",IF(B2=1,"ὁμώνυμον",IF(B2=2,"διὰ πασῶν",IF(B2=3,"διὰ πέντε",IF(B2=4,"διὰ τεσσάρων","?"))))) -> — | E2: — | F2: =IF(A2=0,"START",IF(A2=25,"MIRROR AXIS",IF(A2=50,"END",IF(A2=51,"NEXT CYCLE","—")))) -> START | G2: =REPT("█",B2)
A3: =A2+1 -> 1 | B3: ='Pentametric Cycle'!H3 -> 1 | C3: =IF(B3=0,"—",IF(B3=1,"unison (1:1)",IF(B3=2,"octave (2:1)",IF(B3=3,"fifth (3:2)",IF(B3=4,"fourth (4:3)","?"))))) -> unison (1:1) | D3: =IF(B3=0,"—",IF(B3=1,"ὁμώνυμον",IF(B3=2,"διὰ πασῶν",IF(B3=3,"διὰ πέντε",IF(B3=4,"διὰ τεσσάρων","?"))))) -> ὁμώνυμον | E3: =IF(B3=0,"—",IF(B3=1,"homonymous",IF(B3=2,"through all",IF(B3=3,"through five",IF(B3=4,"through four","?"))))) -> homonymous | F3: =IF(A3=0,"START",IF(A3=25,"MIRROR AXIS",IF(A3=50,"END",IF(A3=51,"NEXT CYCLE","—")))) -> — | G3: =REPT("█",B3) -> █ | H3: =H4+1 -> 24
A4: =A3+1 -> 2 | B4: ='Pentametric Cycle'!H4 -> 0 | C4: =IF(B4=0,"—",IF(B4=1,"unison (1:1)",IF(B4=2,"octave (2:1)",IF(B4=3,"fifth (3:2)",IF(B4=4,"fourth (4:3)","?"))))) -> — | D4: =IF(B4=0,"—",IF(B4=1,"ὁμώνυμον",IF(B4=2,"διὰ πασῶν",IF(B4=3,"διὰ πέντε",IF(B4=4,"διὰ τεσσάρων","?"))))) -> — | E4: =IF(B4=0,"—",IF(B4=1,"homonymous",IF(B4=2,"through all",IF(B4=3,"through five",IF(B4=4,"through four","?"))))) -> — | F4: =IF(A4=0,"START",IF(A4=25,"MIRROR AXIS",IF(A4=50,"END",IF(A4=51,"NEXT CYCLE","—")))) -> — | G4: =REPT("█",B4) | H4: =H5+1 -> 23
A5: =A4+1 -> 3 | B5: ='Pentametric Cycle'!H5 -> 1 | C5: =IF(B5=0,"—",IF(B5=1,"unison (1:1)",IF(B5=2,"octave (2:1)",IF(B5=3,"fifth (3:2)",IF(B5=4,"fourth (4:3)","?"))))) -> unison (1:1) | D5: =IF(B5=0,"—",IF(B5=1,"ὁμώνυμον",IF(B5=2,"διὰ πασῶν",IF(B5=3,"διὰ πέντε",IF(B5=4,"διὰ τεσσάρων","?"))))) -> ὁμώνυμον | E5: =IF(B5=0,"—",IF(B5=1,"homonymous",IF(B5=2,"through all",IF(B5=3,"through five",IF(B5=4,"through four","?"))))) -> homonymous | F5: =IF(A5=0,"START",IF(A5=25,"MIRROR AXIS",IF(A5=50,"END",IF(A5=51,"NEXT CYCLE","—")))) -> — | G5: =REPT("█",B5) -> █ | H5: =H6+1 -> 22
A6: =A5+1 -> 4 | B6: ='Pentametric Cycle'!H6 -> 4 | C6: =IF(B6=0,"—",IF(B6=1,"unison (1:1)",IF(B6=2,"octave (2:1)",IF(B6=3,"fifth (3:2)",IF(B6=4,"fourth (4:3)","?"))))) -> fourth (4:3) | D6: =IF(B6=0,"—",IF(B6=1,"ὁμώνυμον",IF(B6=2,"διὰ πασῶν",IF(B6=3,"διὰ πέντε",IF(B6=4,"διὰ τεσσάρων","?"))))) -> διὰ τεσσάρων | E6: =IF(B6=0,"—",IF(B6=1,"homonymous",IF(B6=2,"through all",IF(B6=3,"through five",IF(B6=4,"through four","?"))))) -> through four | F6: =IF(A6=0,"START",IF(A6=25,"MIRROR AXIS",IF(A6=50,"END",IF(A6=51,"NEXT CYCLE","—")))) -> — | G6: =REPT("█",B6) -> ████ | H6: =H7+1 -> 21
A7: =A6+1 -> 5 | B7: ='Pentametric Cycle'!H7 -> 0 | C7: =IF(B7=0,"—",IF(B7=1,"unison (1:1)",IF(B7=2,"octave (2:1)",IF(B7=3,"fifth (3:2)",IF(B7=4,"fourth (4:3)","?"))))) -> — | D7: =IF(B7=0,"—",IF(B7=1,"ὁμώνυμον",IF(B7=2,"διὰ πασῶν",IF(B7=3,"διὰ πέντε",IF(B7=4,"διὰ τεσσάρων","?"))))) -> — | E7: =IF(B7=0,"—",IF(B7=1,"homonymous",IF(B7=2,"through all",IF(B7=3,"through five",IF(B7=4,"through four","?"))))) -> — | F7: =IF(A7=0,"START",IF(A7=25,"MIRROR AXIS",IF(A7=50,"END",IF(A7=51,"NEXT CYCLE","—")))) -> — | G7: =REPT("█",B7) | H7: =H8+1 -> 20
A8: =A7+1 -> 6 | B8: ='Pentametric Cycle'!H8 -> 3 | C8: =IF(B8=0,"—",IF(B8=1,"unison (1:1)",IF(B8=2,"octave (2:1)",IF(B8=3,"fifth (3:2)",IF(B8=4,"fourth (4:3)","?"))))) -> fifth (3:2) | D8: =IF(B8=0,"—",IF(B8=1,"ὁμώνυμον",IF(B8=2,"διὰ πασῶν",IF(B8=3,"διὰ πέντε",IF(B8=4,"διὰ τεσσάρων","?"))))) -> διὰ πέντε | E8: =IF(B8=0,"—",IF(B8=1,"homonymous",IF(B8=2,"through all",IF(B8=3,"through five",IF(B8=4,"through four","?"))))) -> through five | F8: =IF(A8=0,"START",IF(A8=25,"MIRROR AXIS",IF(A8=50,"END",IF(A8=51,"NEXT CYCLE","—")))) -> — | G8: =REPT("█",B8) -> ███ | H8: =H9+1 -> 19
A9: =A8+1 -> 7 | B9: ='Pentametric Cycle'!H9 -> 4 | C9: =IF(B9=0,"—",IF(B9=1,"unison (1:1)",IF(B9=2,"octave (2:1)",IF(B9=3,"fifth (3:2)",IF(B9=4,"fourth (4:3)","?"))))) -> fourth (4:3) | D9: =IF(B9=0,"—",IF(B9=1,"ὁμώνυμον",IF(B9=2,"διὰ πασῶν",IF(B9=3,"διὰ πέντε",IF(B9=4,"διὰ τεσσάρων","?"))))) -> διὰ τεσσάρων | E9: =IF(B9=0,"—",IF(B9=1,"homonymous",IF(B9=2,"through all",IF(B9=3,"through five",IF(B9=4,"through four","?"))))) -> through four | F9: =IF(A9=0,"START",IF(A9=25,"MIRROR AXIS",IF(A9=50,"END",IF(A9=51,"NEXT CYCLE","—")))) -> — | G9: =REPT("█",B9) -> ████ | H9: =H10+1 -> 18
A10: =A9+1 -> 8 | B10: ='Pentametric Cycle'!H10 -> 2 | C10: =IF(B10=0,"—",IF(B10=1,"unison (1:1)",IF(B10=2,"octave (2:1)",IF(B10=3,"fifth (3:2)",IF(B10=4,"fourth (4:3)","?"))))) -> octave (2:1) | D10: =IF(B10=0,"—",IF(B10=1,"ὁμώνυμον",IF(B10=2,"διὰ πασῶν",IF(B10=3,"διὰ πέντε",IF(B10=4,"διὰ τεσσάρων","?"))))) -> διὰ πασῶν | E10: =IF(B10=0,"—",IF(B10=1,"homonymous",IF(B10=2,"through all",IF(B10=3,"through five",IF(B10=4,"through four","?"))))) -> through all | F10: =IF(A10=0,"START",IF(A10=25,"MIRROR AXIS",IF(A10=50,"END",IF(A10=51,"NEXT CYCLE","—")))) -> — | G10: =REPT("█",B10) -> ██ | H10: =H11+1 -> 17
A11: =A10+1 -> 9 | B11: ='Pentametric Cycle'!H11 -> 2 | C11: =IF(B11=0,"—",IF(B11=1,"unison (1:1)",IF(B11=2,"octave (2:1)",IF(B11=3,"fifth (3:2)",IF(B11=4,"fourth (4:3)","?"))))) -> octave (2:1) | D11: =IF(B11=0,"—",IF(B11=1,"ὁμώνυμον",IF(B11=2,"διὰ πασῶν",IF(B11=3,"διὰ πέντε",IF(B11=4,"διὰ τεσσάρων","?"))))) -> διὰ πασῶν | E11: =IF(B11=0,"—",IF(B11=1,"homonymous",IF(B11=2,"through all",IF(B11=3,"through five",IF(B11=4,"through four","?"))))) -> through all | F11: =IF(A11=0,"START",IF(A11=25,"MIRROR AXIS",IF(A11=50,"END",IF(A11=51,"NEXT CYCLE","—")))) -> — | G11: =REPT("█",B11) -> ██ | H11: =H12+1 -> 16
A12: =A11+1 -> 10 | B12: ='Pentametric Cycle'!H12 -> 0 | C12: =IF(B12=0,"—",IF(B12=1,"unison (1:1)",IF(B12=2,"octave (2:1)",IF(B12=3,"fifth (3:2)",IF(B12=4,"fourth (4:3)","?"))))) -> — | D12: =IF(B12=0,"—",IF(B12=1,"ὁμώνυμον",IF(B12=2,"διὰ πασῶν",IF(B12=3,"διὰ πέντε",IF(B12=4,"διὰ τεσσάρων","?"))))) -> — | E12: =IF(B12=0,"—",IF(B12=1,"homonymous",IF(B12=2,"through all",IF(B12=3,"through five",IF(B12=4,"through four","?"))))) -> — | F12: =IF(A12=0,"START",IF(A12=25,"MIRROR AXIS",IF(A12=50,"END",IF(A12=51,"NEXT CYCLE","—")))) -> — | G12: =REPT("█",B12) | H12: =H13+1 -> 15
A13: =A12+1 -> 11 | B13: ='Pentametric Cycle'!H13 -> 0 | C13: =IF(B13=0,"—",IF(B13=1,"unison (1:1)",IF(B13=2,"octave (2:1)",IF(B13=3,"fifth (3:2)",IF(B13=4,"fourth (4:3)","?"))))) -> — | D13: =IF(B13=0,"—",IF(B13=1,"ὁμώνυμον",IF(B13=2,"διὰ πασῶν",IF(B13=3,"διὰ πέντε",IF(B13=4,"διὰ τεσσάρων","?"))))) -> — | E13: =IF(B13=0,"—",IF(B13=1,"homonymous",IF(B13=2,"through all",IF(B13=3,"through five",IF(B13=4,"through four","?"))))) -> — | F13: =IF(A13=0,"START",IF(A13=25,"MIRROR AXIS",IF(A13=50,"END",IF(A13=51,"NEXT CYCLE","—")))) -> — | G13: =REPT("█",B13) | H13: =H14+1 -> 14
A14: =A13+1 -> 12 | B14: ='Pentametric Cycle'!H14 -> 3 | C14: =IF(B14=0,"—",IF(B14=1,"unison (1:1)",IF(B14=2,"octave (2:1)",IF(B14=3,"fifth (3:2)",IF(B14=4,"fourth (4:3)","?"))))) -> fifth (3:2) | D14: =IF(B14=0,"—",IF(B14=1,"ὁμώνυμον",IF(B14=2,"διὰ πασῶν",IF(B14=3,"διὰ πέντε",IF(B14=4,"διὰ τεσσάρων","?"))))) -> διὰ πέντε | E14: =IF(B14=0,"—",IF(B14=1,"homonymous",IF(B14=2,"through all",IF(B14=3,"through five",IF(B14=4,"through four","?"))))) -> through five | F14: =IF(A14=0,"START",IF(A14=25,"MIRROR AXIS",IF(A14=50,"END",IF(A14=51,"NEXT CYCLE","—")))) -> — | G14: =REPT("█",B14) -> ███ | H14: =H15+1 -> 13
... A25: =A24+1 -> 23 | B25: ='Pentametric Cycle'!H25 -> 0 | C25: =IF(B25=0,"—",IF(B25=1,"unison (1:1)",IF(B25=2,"octave (2:1)",IF(B25=3,"fifth (3:2)",IF(B25=4,"fourth (4:3)","?"))))) -> — | D25: =IF(B25=0,"—",IF(B25=1,"ὁμώνυμον",IF(B25=2,"διὰ πασῶν",IF(B25=3,"διὰ πέντε",IF(B25=4,"διὰ τεσσάρων","?"))))) -> — | E25: =IF(B25=0,"—",IF(B25=1,"homonymous",IF(B25=2,"through all",IF(B25=3,"through five",IF(B25=4,"through four","?"))))) -> — | F25: =IF(A25=0,"START",IF(A25=25,"MIRROR AXIS",IF(A25=50,"END",IF(A25=51,"NEXT CYCLE","—")))) -> — | G25: =REPT("█",B25) | H25: =H26+1 -> 2
A26: =A25+1 -> 24 | B26: ='Pentametric Cycle'!H26 -> 1 | C26: =IF(B26=0,"—",IF(B26=1,"unison (1:1)",IF(B26=2,"octave (2:1)",IF(B26=3,"fifth (3:2)",IF(B26=4,"fourth (4:3)","?"))))) -> unison (1:1) | D26: =IF(B26=0,"—",IF(B26=1,"ὁμώνυμον",IF(B26=2,"διὰ πασῶν",IF(B26=3,"διὰ πέντε",IF(B26=4,"διὰ τεσσάρων","?"))))) -> ὁμώνυμον | E26: =IF(B26=0,"—",IF(B26=1,"homonymous",IF(B26=2,"through all",IF(B26=3,"through five",IF(B26=4,"through four","?"))))) -> homonymous | F26: =IF(A26=0,"START",IF(A26=25,"MIRROR AXIS",IF(A26=50,"END",IF(A26=51,"NEXT CYCLE","—")))) -> — | G26: =REPT("█",B26) -> █ | H26: 1
A27: =A26+1 -> 25 | B27: ='Pentametric Cycle'!H27 -> 0 | C27: =IF(B27=0,"—",IF(B27=1,"unison (1:1)",IF(B27=2,"octave (2:1)",IF(B27=3,"fifth (3:2)",IF(B27=4,"fourth (4:3)","?"))))) -> — | D27: =IF(B27=0,"—",IF(B27=1,"ὁμώνυμον",IF(B27=2,"διὰ πασῶν",IF(B27=3,"διὰ πέντε",IF(B27=4,"διὰ τεσσάρων","?"))))) -> — | E27: =IF(B27=0,"—",IF(B27=1,"homonymous",IF(B27=2,"through all",IF(B27=3,"through five",IF(B27=4,"through four","?"))))) -> — | F27: =IF(A27=0,"START",IF(A27=25,"MIRROR AXIS",IF(A27=50,"END",IF(A27=51,"NEXT CYCLE","—")))) -> MIRROR AXIS | G27: =REPT("█",B27)
A28: =A27+1 -> 26 | B28: ='Pentametric Cycle'!H28 -> 1 | C28: =IF(B28=0,"—",IF(B28=1,"unison (1:1)",IF(B28=2,"octave (2:1)",IF(B28=3,"fifth (3:2)",IF(B28=4,"fourth (4:3)","?"))))) -> unison (1:1) | D28: =IF(B28=0,"—",IF(B28=1,"ὁμώνυμον",IF(B28=2,"διὰ πασῶν",IF(B28=3,"διὰ πέντε",IF(B28=4,"διὰ τεσσάρων","?"))))) -> ὁμώνυμον | E28: =IF(B28=0,"—",IF(B28=1,"homonymous",IF(B28=2,"through all",IF(B28=3,"through five",IF(B28=4,"through four","?"))))) -> homonymous | F28: =IF(A28=0,"START",IF(A28=25,"MIRROR AXIS",IF(A28=50,"END",IF(A28=51,"NEXT CYCLE","—")))) -> — | G28: =REPT("█",B28) -> █ | H28: 1
A29: =A28+1 -> 27 | B29: ='Pentametric Cycle'!H29 -> 0 | C29: =IF(B29=0,"—",IF(B29=1,"unison (1:1)",IF(B29=2,"octave (2:1)",IF(B29=3,"fifth (3:2)",IF(B29=4,"fourth (4:3)","?"))))) -> — | D29: =IF(B29=0,"—",IF(B29=1,"ὁμώνυμον",IF(B29=2,"διὰ πασῶν",IF(B29=3,"διὰ πέντε",IF(B29=4,"διὰ τεσσάρων","?"))))) -> — | E29: =IF(B29=0,"—",IF(B29=1,"homonymous",IF(B29=2,"through all",IF(B29=3,"through five",IF(B29=4,"through four","?"))))) -> — | F29: =IF(A29=0,"START",IF(A29=25,"MIRROR AXIS",IF(A29=50,"END",IF(A29=51,"NEXT CYCLE","—")))) -> — | G29: =REPT("█",B29) | H29: =H28+1 -> 2
A30: =A29+1 -> 28 | B30: ='Pentametric Cycle'!H30 -> 1 | C30: =IF(B30=0,"—",IF(B30=1,"unison (1:1)",IF(B30=2,"octave (2:1)",IF(B30=3,"fifth (3:2)",IF(B30=4,"fourth (4:3)","?"))))) -> unison (1:1) | D30: =IF(B30=0,"—",IF(B30=1,"ὁμώνυμον",IF(B30=2,"διὰ πασῶν",IF(B30=3,"διὰ πέντε",IF(B30=4,"διὰ τεσσάρων","?"))))) -> ὁμώνυμον | E30: =IF(B30=0,"—",IF(B30=1,"homonymous",IF(B30=2,"through all",IF(B30=3,"through five",IF(B30=4,"through four","?"))))) -> homonymous | F30: =IF(A30=0,"START",IF(A30=25,"MIRROR AXIS",IF(A30=50,"END",IF(A30=51,"NEXT CYCLE","—")))) -> — | G30: =REPT("█",B30) -> █ | H30: =H29+1 -> 3
A31: =A30+1 -> 29 | B31: ='Pentametric Cycle'!H31 -> 4 | C31: =IF(B31=0,"—",IF(B31=1,"unison (1:1)",IF(B31=2,"octave (2:1)",IF(B31=3,"fifth (3:2)",IF(B31=4,"fourth (4:3)","?"))))) -> fourth (4:3) | D31: =IF(B31=0,"—",IF(B31=1,"ὁμώνυμον",IF(B31=2,"διὰ πασῶν",IF(B31=3,"διὰ πέντε",IF(B31=4,"διὰ τεσσάρων","?"))))) -> διὰ τεσσάρων | E31: =IF(B31=0,"—",IF(B31=1,"homonymous",IF(B31=2,"through all",IF(B31=3,"through five",IF(B31=4,"through four","?"))))) -> through four | F31: =IF(A31=0,"START",IF(A31=25,"MIRROR AXIS",IF(A31=50,"END",IF(A31=51,"NEXT CYCLE","—")))) -> — | G31: =REPT("█",B31) -> ████ | H31: =H30+1 -> 4
A32: =A31+1 -> 30 | B32: ='Pentametric Cycle'!H32 -> 0 | C32: =IF(B32=0,"—",IF(B32=1,"unison (1:1)",IF(B32=2,"octave (2:1)",IF(B32=3,"fifth (3:2)",IF(B32=4,"fourth (4:3)","?"))))) -> — | D32: =IF(B32=0,"—",IF(B32=1,"ὁμώνυμον",IF(B32=2,"διὰ πασῶν",IF(B32=3,"διὰ πέντε",IF(B32=4,"διὰ τεσσάρων","?"))))) -> — | E32: =IF(B32=0,"—",IF(B32=1,"homonymous",IF(B32=2,"through all",IF(B32=3,"through five",IF(B32=4,"through four","?"))))) -> — | F32: =IF(A32=0,"START",IF(A32=25,"MIRROR AXIS",IF(A32=50,"END",IF(A32=51,"NEXT CYCLE","—")))) -> — | G32: =REPT("█",B32) | H32: =H31+1 -> 5
A33: =A32+1 -> 31 | B33: ='Pentametric Cycle'!H33 -> 3 | C33: =IF(B33=0,"—",IF(B33=1,"unison (1:1)",IF(B33=2,"octave (2:1)",IF(B33=3,"fifth (3:2)",IF(B33=4,"fourth (4:3)","?"))))) -> fifth (3:2) | D33: =IF(B33=0,"—",IF(B33=1,"ὁμώνυμον",IF(B33=2,"διὰ πασῶν",IF(B33=3,"διὰ πέντε",IF(B33=4,"διὰ τεσσάρων","?"))))) -> διὰ πέντε | E33: =IF(B33=0,"—",IF(B33=1,"homonymous",IF(B33=2,"through all",IF(B33=3,"through five",IF(B33=4,"through four","?"))))) -> through five | F33: =IF(A33=0,"START",IF(A33=25,"MIRROR AXIS",IF(A33=50,"END",IF(A33=51,"NEXT CYCLE","—")))) -> — | G33: =REPT("█",B33) -> ███ | H33: =H32+1 -> 6
A34: =A33+1 -> 32 | B34: ='Pentametric Cycle'!H34 -> 4 | C34: =IF(B34=0,"—",IF(B34=1,"unison (1:1)",IF(B34=2,"octave (2:1)",IF(B34=3,"fifth (3:2)",IF(B34=4,"fourth (4:3)","?"))))) -> fourth (4:3) | D34: =IF(B34=0,"—",IF(B34=1,"ὁμώνυμον",IF(B34=2,"διὰ πασῶν",IF(B34=3,"διὰ πέντε",IF(B34=4,"διὰ τεσσάρων","?"))))) -> διὰ τεσσάρων | E34: =IF(B34=0,"—",IF(B34=1,"homonymous",IF(B34=2,"through all",IF(B34=3,"through five",IF(B34=4,"through four","?"))))) -> through four | F34: =IF(A34=0,"START",IF(A34=25,"MIRROR AXIS",IF(A34=50,"END",IF(A34=51,"NEXT CYCLE","—")))) -> — | G34: =REPT("█",B34) -> ████ | H34: =H33+1 -> 7
A35: =A34+1 -> 33 | B35: ='Pentametric Cycle'!H35 -> 2 | C35: =IF(B35=0,"—",IF(B35=1,"unison (1:1)",IF(B35=2,"octave (2:1)",IF(B35=3,"fifth (3:2)",IF(B35=4,"fourth (4:3)","?"))))) -> octave (2:1) | D35: =IF(B35=0,"—",IF(B35=1,"ὁμώνυμον",IF(B35=2,"διὰ πασῶν",IF(B35=3,"διὰ πέντε",IF(B35=4,"διὰ τεσσάρων","?"))))) -> διὰ πασῶν | E35: =IF(B35=0,"—",IF(B35=1,"homonymous",IF(B35=2,"through all",IF(B35=3,"through five",IF(B35=4,"through four","?"))))) -> through all | F35: =IF(A35=0,"START",IF(A35=25,"MIRROR AXIS",IF(A35=50,"END",IF(A35=51,"NEXT CYCLE","—")))) -> — | G35: =REPT("█",B35) -> ██ | H35: =H34+1 -> 8
A36: =A35+1 -> 34 | B36: ='Pentametric Cycle'!H36 -> 2 | C36: =IF(B36=0,"—",IF(B36=1,"unison (1:1)",IF(B36=2,"octave (2:1)",IF(B36=3,"fifth (3:2)",IF(B36=4,"fourth (4:3)","?"))))) -> octave (2:1) | D36: =IF(B36=0,"—",IF(B36=1,"ὁμώνυμον",IF(B36=2,"διὰ πασῶν",IF(B36=3,"διὰ πέντε",IF(B36=4,"διὰ τεσσάρων","?"))))) -> διὰ πασῶν | E36: =IF(B36=0,"—",IF(B36=1,"homonymous",IF(B36=2,"through all",IF(B36=3,"through five",IF(B36=4,"through four","?"))))) -> through all | F36: =IF(A36=0,"START",IF(A36=25,"MIRROR AXIS",IF(A36=50,"END",IF(A36=51,"NEXT CYCLE","—")))) -> — | G36: =REPT("█",B36) -> ██ | H36: =H35+1 -> 9
A37: =A36+1 -> 35 | B37: ='Pentametric Cycle'!H37 -> 0 | C37: =IF(B37=0,"—",IF(B37=1,"unison (1:1)",IF(B37=2,"octave (2:1)",IF(B37=3,"fifth (3:2)",IF(B37=4,"fourth (4:3)","?"))))) -> — | D37: =IF(B37=0,"—",IF(B37=1,"ὁμώνυμον",IF(B37=2,"διὰ πασῶν",IF(B37=3,"διὰ πέντε",IF(B37=4,"διὰ τεσσάρων","?"))))) -> — | E37: =IF(B37=0,"—",IF(B37=1,"homonymous",IF(B37=2,"through all",IF(B37=3,"through five",IF(B37=4,"through four","?"))))) -> — | F37: =IF(A37=0,"START",IF(A37=25,"MIRROR AXIS",IF(A37=50,"END",IF(A37=51,"NEXT CYCLE","—")))) -> — | G37: =REPT("█",B37) | H37: =H36+1 -> 10
A38: =A37+1 -> 36 | B38: ='Pentametric Cycle'!H38 -> 0 | C38: =IF(B38=0,"—",IF(B38=1,"unison (1:1)",IF(B38=2,"octave (2:1)",IF(B38=3,"fifth (3:2)",IF(B38=4,"fourth (4:3)","?"))))) -> — | D38: =IF(B38=0,"—",IF(B38=1,"ὁμώνυμον",IF(B38=2,"διὰ πασῶν",IF(B38=3,"διὰ πέντε",IF(B38=4,"διὰ τεσσάρων","?"))))) -> — | E38: =IF(B38=0,"—",IF(B38=1,"homonymous",IF(B38=2,"through all",IF(B38=3,"through five",IF(B38=4,"through four","?"))))) -> — | F38: =IF(A38=0,"START",IF(A38=25,"MIRROR AXIS",IF(A38=50,"END",IF(A38=51,"NEXT CYCLE","—")))) -> — | G38: =REPT("█",B38) | H38: =H37+1 -> 11
A39: =A38+1 -> 37 | B39: ='Pentametric Cycle'!H39 -> 3 | C39: =IF(B39=0,"—",IF(B39=1,"unison (1:1)",IF(B39=2,"octave (2:1)",IF(B39=3,"fifth (3:2)",IF(B39=4,"fourth (4:3)","?"))))) -> fifth (3:2) | D39: =IF(B39=0,"—",IF(B39=1,"ὁμώνυμον",IF(B39=2,"διὰ πασῶν",IF(B39=3,"διὰ πέντε",IF(B39=4,"διὰ τεσσάρων","?"))))) -> διὰ πέντε | E39: =IF(B39=0,"—",IF(B39=1,"homonymous",IF(B39=2,"through all",IF(B39=3,"through five",IF(B39=4,"through four","?"))))) -> through five | F39: =IF(A39=0,"START",IF(A39=25,"MIRROR AXIS",IF(A39=50,"END",IF(A39=51,"NEXT CYCLE","—")))) -> — | G39: =REPT("█",B39) -> ███ | H39: =H38+1 -> 12
A40: =A39+1 -> 38 | B40: ='Pentametric Cycle'!H40 -> 3 | C40: =IF(B40=0,"—",IF(B40=1,"unison (1:1)",IF(B40=2,"octave (2:1)",IF(B40=3,"fifth (3:2)",IF(B40=4,"fourth (4:3)","?"))))) -> fifth (3:2) | D40: =IF(B40=0,"—",IF(B40=1,"ὁμώνυμον",IF(B40=2,"διὰ πασῶν",IF(B40=3,"διὰ πέντε",IF(B40=4,"διὰ τεσσάρων","?"))))) -> διὰ πέντε | E40: =IF(B40=0,"—",IF(B40=1,"homonymous",IF(B40=2,"through all",IF(B40=3,"through five",IF(B40=4,"through four","?"))))) -> through five | F40: =IF(A40=0,"START",IF(A40=25,"MIRROR AXIS",IF(A40=50,"END",IF(A40=51,"NEXT CYCLE","—")))) -> — | G40: =REPT("█",B40) -> ███ | H40: =H39+1 -> 13
... A51: =A50+1 -> 49 | B51: ='Pentametric Cycle'!H51 -> 1 | C51: =IF(B51=0,"—",IF(B51=1,"unison (1:1)",IF(B51=2,"octave (2:1)",IF(B51=3,"fifth (3:2)",IF(B51=4,"fourth (4:3)","?"))))) -> unison (1:1) | D51: =IF(B51=0,"—",IF(B51=1,"ὁμώνυμον",IF(B51=2,"διὰ πασῶν",IF(B51=3,"διὰ πέντε",IF(B51=4,"διὰ τεσσάρων","?"))))) -> ὁμώνυμον | E51: =IF(B51=0,"—",IF(B51=1,"homonymous",IF(B51=2,"through all",IF(B51=3,"through five",IF(B51=4,"through four","?"))))) -> homonymous | F51: =IF(A51=0,"START",IF(A51=25,"MIRROR AXIS",IF(A51=50,"END",IF(A51=51,"NEXT CYCLE","—")))) -> — | G51: =REPT("█",B51) -> █ | H51: =H50+1 -> 24
A52: =A51+1 -> 50 | B52: ='Pentametric Cycle'!H52 -> 0 | C52: =IF(B52=0,"—",IF(B52=1,"unison (1:1)",IF(B52=2,"octave (2:1)",IF(B52=3,"fifth (3:2)",IF(B52=4,"fourth (4:3)","?"))))) -> — | D52: =IF(B52=0,"—",IF(B52=1,"ὁμώνυμον",IF(B52=2,"διὰ πασῶν",IF(B52=3,"διὰ πέντε",IF(B52=4,"διὰ τεσσάρων","?"))))) -> — | E52: =IF(B52=0,"—",IF(B52=1,"homonymous",IF(B52=2,"through all",IF(B52=3,"through five",IF(B52=4,"through four","?"))))) -> — | F52: =IF(A52=0,"START",IF(A52=25,"MIRROR AXIS",IF(A52=50,"END",IF(A52=51,"NEXT CYCLE","—")))) -> END | G52: =REPT("█",B52)
A53: =A52+1 -> 51 | B53: ='Pentametric Cycle'!H53 -> 1 | C53: =IF(B53=0,"—",IF(B53=1,"unison (1:1)",IF(B53=2,"octave (2:1)",IF(B53=3,"fifth (3:2)",IF(B53=4,"fourth (4:3)","?"))))) -> unison (1:1) | D53: =IF(B53=0,"—",IF(B53=1,"ὁμώνυμον",IF(B53=2,"διὰ πασῶν",IF(B53=3,"διὰ πέντε",IF(B53=4,"διὰ τεσσάρων","?"))))) -> ὁμώνυμον | E53: =IF(B53=0,"—",IF(B53=1,"homonymous",IF(B53=2,"through all",IF(B53=3,"through five",IF(B53=4,"through four","?"))))) -> homonymous | F53: =IF(A53=0,"START",IF(A53=25,"MIRROR AXIS",IF(A53=50,"END",IF(A53=51,"NEXT CYCLE","—")))) -> NEXT CYCLE | G53: =REPT("█",B53) -> █
A54: =A53+1 -> 52 | B54: ='Pentametric Cycle'!H54 -> 0 | C54: =IF(B54=0,"—",IF(B54=1,"unison (1:1)",IF(B54=2,"octave (2:1)",IF(B54=3,"fifth (3:2)",IF(B54=4,"fourth (4:3)","?"))))) -> — | D54: =IF(B54=0,"—",IF(B54=1,"ὁμώνυμον",IF(B54=2,"διὰ πασῶν",IF(B54=3,"διὰ πέντε",IF(B54=4,"διὰ τεσσάρων","?"))))) -> — | E54: =IF(B54=0,"—",IF(B54=1,"homonymous",IF(B54=2,"through all",IF(B54=3,"through five",IF(B54=4,"through four","?"))))) -> — | F54: =IF(A54=0,"START",IF(A54=25,"MIRROR AXIS",IF(A54=50,"END",IF(A54=51,"NEXT CYCLE","—")))) -> — | G54: =REPT("█",B54)

Sheet Interval Map Table
A1: m | B1: C(m) | C1: Ratio | D1: Interval | E1: Greek
A2: 0 | B2: =(26*A2-5*A2^2)/24 -> 0 | C2: =B2&":1" -> 0:1 | D2: origin | E2: —
A3: 2 | B3: =(26*A3-5*A3^2)/24 -> 1.3333333 | C3: =B3&":1" -> 1.33333333333333:1 | D3: fourth | E3: διὰ τεσσάρων
A4: 4 | B4: =(26*A4-5*A4^2)/24 -> 1 | C4: =B4&":1" -> 1:1 | D4: unison | E4: ὁμώνυμον
A5: 6 | B5: =(26*A5-5*A5^2)/24 -> -1 | C5: =B5&":1" -> -1:1 | D5: inversion | E5: ἀντιστροφή
A6: 8 | B6: =(26*A6-5*A6^2)/24 -> -4.6666667 | C6: =B6&":1" -> -4.66666666666667:1 | D6: apotome | E6: ἀποτομή
A8: Note:
A9: C(m) is the Interval Map (Ὁ Διαστηματικὸς Χάρτης)
A10: Also called the Harmonic Canon (Ὁ Ἁρμονικὸς Κανών)

Sheet Summary
A1: Ὁ Πενταμετρικὸς Κύκλος
A2: The Pentametric Cycle
A4: Formula:
A5: s(n)² = (n² + 4C(m))/5
A6: m = 4n² mod 10
A7: C(m) = (26m − 5m²)/24
A9: Structure:
A10: Fundamental period: 25 terms = 5²
A11: Transitions: 24 = 4!
A12: Axis: 1 (n=25)
A13: Consonance skeleton: 16 = 4²
A14: Silence skeleton: 9 = 3²
... A33: Ὁ Διαστηματικὸς Χάρτης — The Interval Map

Sheet Silence as 5
A1: n | B1: m = 4n² mod 10 | C1: C(m) = (26m − 5m²)/24 | D1: 𝔓(n) = (n² + 4C(m))/5 | E1: H = 𝔓 mod 5 | F1: i (no 0) = 1 + MOD(𝔓 − 1; 5) | G1: i/i−1 (step) | H1: step as text | I1: step in one octave | J1: interval of the step | K1: reading A: i:(i−1) | L1: check: step × step at 51 − n
A2: 0 | B2: =MOD(4*A2^2,10) -> 0 | C2: =(26*B2-5*B2^2)/24 -> 0 | D2: =(A2^2+4*C2)/5 -> 0 | E2: =MOD(D2,5) -> 0 | F2: =1+MOD(D2-1,5) -> 5 | K2: =IF(F2=1,"1:1",F2&":"&(F2-1)) -> 5:4 | N2: Intervals in one octave
A3: =A2+1 -> 1 | B3: =MOD(4*A3^2,10) -> 4 | C3: =(26*B3-5*B3^2)/24 -> 1 | D3: =(A3^2+4*C3)/5 -> 1 | E3: =MOD(D3,5) -> 1 | F3: =1+MOD(D3-1,5) -> 1 | G3: =F3/F2 -> 0.2 | H3: =F3&"/"&F2 -> 1/5 | I3: =G3/2^FLOOR(LOG(G3,2),1) -> 1.6 | J3: =INDEX($O$4:$O$10,MATCH(ROUND(I3,6),$N$4:$N$10,0)) -> minor sixth | K3: =IF(F3=1,"1:1",F3&":"&(F3-1)) -> 1:1 | L3: =ROUND(G3*INDEX($G$2:$G$52,51-A3+1),9) -> 1 | N3: value | O3: interval | P3: ratio | Q3: steps per period (n = 1–25)
A4: =A3+1 -> 2 | B4: =MOD(4*A4^2,10) -> 6 | C4: =(26*B4-5*B4^2)/24 -> -1 | D4: =(A4^2+4*C4)/5 -> 0 | E4: =MOD(D4,5) -> 0 | F4: =1+MOD(D4-1,5) -> 5 | G4: =F4/F3 -> 5 | H4: =F4&"/"&F3 -> 5/1 | I4: =G4/2^FLOOR(LOG(G4,2),1) -> 1.25 | J4: =INDEX($O$4:$O$10,MATCH(ROUND(I4,6),$N$4:$N$10,0)) -> major third | K4: =IF(F4=1,"1:1",F4&":"&(F4-1)) -> 5:4 | L4: =ROUND(G4*INDEX($G$2:$G$52,51-A4+1),9) -> 1 | N4: =ROUND(1,6) -> 1 | O4: unison / octave(s) | P4: 1/1 | Q4: =COUNTIF($J$3:$J$27,O4) -> 9
A5: =A4+1 -> 3 | B5: =MOD(4*A5^2,10) -> 6 | C5: =(26*B5-5*B5^2)/24 -> -1 | D5: =(A5^2+4*C5)/5 -> 1 | E5: =MOD(D5,5) -> 1 | F5: =1+MOD(D5-1,5) -> 1 | G5: =F5/F4 -> 0.2 | H5: =F5&"/"&F4 -> 1/5 | I5: =G5/2^FLOOR(LOG(G5,2),1) -> 1.6 | J5: =INDEX($O$4:$O$10,MATCH(ROUND(I5,6),$N$4:$N$10,0)) -> minor sixth | K5: =IF(F5=1,"1:1",F5&":"&(F5-1)) -> 1:1 | L5: =ROUND(G5*INDEX($G$2:$G$52,51-A5+1),9) -> 1 | N5: =ROUND(6/5,6) -> 1.2 | O5: minor third | P5: 6/5 | Q5: =COUNTIF($J$3:$J$27,O5) -> 2
A6: =A5+1 -> 4 | B6: =MOD(4*A6^2,10) -> 4 | C6: =(26*B6-5*B6^2)/24 -> 1 | D6: =(A6^2+4*C6)/5 -> 4 | E6: =MOD(D6,5) -> 4 | F6: =1+MOD(D6-1,5) -> 4 | G6: =F6/F5 -> 4 | H6: =F6&"/"&F5 -> 4/1 | I6: =G6/2^FLOOR(LOG(G6,2),1) -> 1 | J6: =INDEX($O$4:$O$10,MATCH(ROUND(I6,6),$N$4:$N$10,0)) -> unison / octave(s) | K6: =IF(F6=1,"1:1",F6&":"&(F6-1)) -> 4:3 | L6: =ROUND(G6*INDEX($G$2:$G$52,51-A6+1),9) -> 1 | N6: =ROUND(5/4,6) -> 1.25 | O6: major third | P6: 5/4 | Q6: =COUNTIF($J$3:$J$27,O6) -> 5
A7: =A6+1 -> 5 | B7: =MOD(4*A7^2,10) -> 0 | C7: =(26*B7-5*B7^2)/24 -> 0 | D7: =(A7^2+4*C7)/5 -> 5 | E7: =MOD(D7,5) -> 0 | F7: =1+MOD(D7-1,5) -> 5 | G7: =F7/F6 -> 1.25 | H7: =F7&"/"&F6 -> 5/4 | I7: =G7/2^FLOOR(LOG(G7,2),1) -> 1.25 | J7: =INDEX($O$4:$O$10,MATCH(ROUND(I7,6),$N$4:$N$10,0)) -> major third | K7: =IF(F7=1,"1:1",F7&":"&(F7-1)) -> 5:4 | L7: =ROUND(G7*INDEX($G$2:$G$52,51-A7+1),9) -> 1 | N7: =ROUND(4/3,6) -> 1.333333 | O7: fourth | P7: 4/3 | Q7: =COUNTIF($J$3:$J$27,O7) -> 1
A8: =A7+1 -> 6 | B8: =MOD(4*A8^2,10) -> 4 | C8: =(26*B8-5*B8^2)/24 -> 1 | D8: =(A8^2+4*C8)/5 -> 8 | E8: =MOD(D8,5) -> 3 | F8: =1+MOD(D8-1,5) -> 3 | G8: =F8/F7 -> 0.6 | H8: =F8&"/"&F7 -> 3/5 | I8: =G8/2^FLOOR(LOG(G8,2),1) -> 1.2 | J8: =INDEX($O$4:$O$10,MATCH(ROUND(I8,6),$N$4:$N$10,0)) -> minor third | K8: =IF(F8=1,"1:1",F8&":"&(F8-1)) -> 3:2 | L8: =ROUND(G8*INDEX($G$2:$G$52,51-A8+1),9) -> 1 | N8: =ROUND(3/2,6) -> 1.5 | O8: fifth | P8: 3/2 | Q8: =COUNTIF($J$3:$J$27,O8) -> 1
A9: =A8+1 -> 7 | B9: =MOD(4*A9^2,10) -> 6 | C9: =(26*B9-5*B9^2)/24 -> -1 | D9: =(A9^2+4*C9)/5 -> 9 | E9: =MOD(D9,5) -> 4 | F9: =1+MOD(D9-1,5) -> 4 | G9: =F9/F8 -> 1.3333333 | H9: =F9&"/"&F8 -> 4/3 | I9: =G9/2^FLOOR(LOG(G9,2),1) -> 1.3333333 | J9: =INDEX($O$4:$O$10,MATCH(ROUND(I9,6),$N$4:$N$10,0)) -> fourth | K9: =IF(F9=1,"1:1",F9&":"&(F9-1)) -> 4:3 | L9: =ROUND(G9*INDEX($G$2:$G$52,51-A9+1),9) -> 1 | N9: =ROUND(8/5,6) -> 1.6 | O9: minor sixth | P9: 8/5 | Q9: =COUNTIF($J$3:$J$27,O9) -> 5
A10: =A9+1 -> 8 | B10: =MOD(4*A10^2,10) -> 6 | C10: =(26*B10-5*B10^2)/24 -> -1 | D10: =(A10^2+4*C10)/5 -> 12 | E10: =MOD(D10,5) -> 2 | F10: =1+MOD(D10-1,5) -> 2 | G10: =F10/F9 -> 0.5 | H10: =F10&"/"&F9 -> 2/4 | I10: =G10/2^FLOOR(LOG(G10,2),1) -> 1 | J10: =INDEX($O$4:$O$10,MATCH(ROUND(I10,6),$N$4:$N$10,0)) -> unison / octave(s) | K10: =IF(F10=1,"1:1",F10&":"&(F10-1)) -> 2:1 | L10: =ROUND(G10*INDEX($G$2:$G$52,51-A10+1),9) -> 1 | N10: =ROUND(5/3,6) -> 1.666667 | O10: major sixth | P10: 5/3 | Q10: =COUNTIF($J$3:$J$27,O10) -> 2
A11: =A10+1 -> 9 | B11: =MOD(4*A11^2,10) -> 4 | C11: =(26*B11-5*B11^2)/24 -> 1 | D11: =(A11^2+4*C11)/5 -> 17 | E11: =MOD(D11,5) -> 2 | F11: =1+MOD(D11-1,5) -> 2 | G11: =F11/F10 -> 1 | H11: =F11&"/"&F10 -> 2/2 | I11: =G11/2^FLOOR(LOG(G11,2),1) -> 1 | J11: =INDEX($O$4:$O$10,MATCH(ROUND(I11,6),$N$4:$N$10,0)) -> unison / octave(s) | K11: =IF(F11=1,"1:1",F11&":"&(F11-1)) -> 2:1 | L11: =ROUND(G11*INDEX($G$2:$G$52,51-A11+1),9) -> 1 | O11: total | Q11: =SUM(Q4:Q10) -> 25
A12: =A11+1 -> 10 | B12: =MOD(4*A12^2,10) -> 0 | C12: =(26*B12-5*B12^2)/24 -> 0 | D12: =(A12^2+4*C12)/5 -> 20 | E12: =MOD(D12,5) -> 0 | F12: =1+MOD(D12-1,5) -> 5 | G12: =F12/F11 -> 2.5 | H12: =F12&"/"&F11 -> 5/2 | I12: =G12/2^FLOOR(LOG(G12,2),1) -> 1.25 | J12: =INDEX($O$4:$O$10,MATCH(ROUND(I12,6),$N$4:$N$10,0)) -> major third | K12: =IF(F12=1,"1:1",F12&":"&(F12-1)) -> 5:4 | L12: =ROUND(G12*INDEX($G$2:$G$52,51-A12+1),9) -> 1
A13: =A12+1 -> 11 | B13: =MOD(4*A13^2,10) -> 4 | C13: =(26*B13-5*B13^2)/24 -> 1 | D13: =(A13^2+4*C13)/5 -> 25 | E13: =MOD(D13,5) -> 0 | F13: =1+MOD(D13-1,5) -> 5 | G13: =F13/F12 -> 1 | H13: =F13&"/"&F12 -> 5/5 | I13: =G13/2^FLOOR(LOG(G13,2),1) -> 1 | J13: =INDEX($O$4:$O$10,MATCH(ROUND(I13,6),$N$4:$N$10,0)) -> unison / octave(s) | K13: =IF(F13=1,"1:1",F13&":"&(F13-1)) -> 5:4 | L13: =ROUND(G13*INDEX($G$2:$G$52,51-A13+1),9) -> 1 | N13: Reading A: i:(i−1) per period
A14: =A13+1 -> 12 | B14: =MOD(4*A14^2,10) -> 6 | C14: =(26*B14-5*B14^2)/24 -> -1 | D14: =(A14^2+4*C14)/5 -> 28 | E14: =MOD(D14,5) -> 3 | F14: =1+MOD(D14-1,5) -> 3 | G14: =F14/F13 -> 0.6 | H14: =F14&"/"&F13 -> 3/5 | I14: =G14/2^FLOOR(LOG(G14,2),1) -> 1.2 | J14: =INDEX($O$4:$O$10,MATCH(ROUND(I14,6),$N$4:$N$10,0)) -> minor third | K14: =IF(F14=1,"1:1",F14&":"&(F14-1)) -> 3:2 | L14: =ROUND(G14*INDEX($G$2:$G$52,51-A14+1),9) -> 1 | O14: 1:1 | Q14: =COUNTIF($K$2:$K$26,O14) -> 4
A15: =A14+1 -> 13 | B15: =MOD(4*A15^2,10) -> 6 | C15: =(26*B15-5*B15^2)/24 -> -1 | D15: =(A15^2+4*C15)/5 -> 33 | E15: =MOD(D15,5) -> 3 | F15: =1+MOD(D15-1,5) -> 3 | G15: =F15/F14 -> 1 | H15: =F15&"/"&F14 -> 3/3 | I15: =G15/2^FLOOR(LOG(G15,2),1) -> 1 | J15: =INDEX($O$4:$O$10,MATCH(ROUND(I15,6),$N$4:$N$10,0)) -> unison / octave(s) | K15: =IF(F15=1,"1:1",F15&":"&(F15-1)) -> 3:2 | L15: =ROUND(G15*INDEX($G$2:$G$52,51-A15+1),9) -> 1 | O15: 2:1 | Q15: =COUNTIF($K$2:$K$26,O15) -> 4
A16: =A15+1 -> 14 | B16: =MOD(4*A16^2,10) -> 4 | C16: =(26*B16-5*B16^2)/24 -> 1 | D16: =(A16^2+4*C16)/5 -> 40 | E16: =MOD(D16,5) -> 0 | F16: =1+MOD(D16-1,5) -> 5 | G16: =F16/F15 -> 1.6666667 | H16: =F16&"/"&F15 -> 5/3 | I16: =G16/2^FLOOR(LOG(G16,2),1) -> 1.6666667 | J16: =INDEX($O$4:$O$10,MATCH(ROUND(I16,6),$N$4:$N$10,0)) -> major sixth | K16: =IF(F16=1,"1:1",F16&":"&(F16-1)) -> 5:4 | L16: =ROUND(G16*INDEX($G$2:$G$52,51-A16+1),9) -> 1 | O16: 3:2 | Q16: =COUNTIF($K$2:$K$26,O16) -> 4
A17: =A16+1 -> 15 | B17: =MOD(4*A17^2,10) -> 0 | C17: =(26*B17-5*B17^2)/24 -> 0 | D17: =(A17^2+4*C17)/5 -> 45 | E17: =MOD(D17,5) -> 0 | F17: =1+MOD(D17-1,5) -> 5 | G17: =F17/F16 -> 1 | H17: =F17&"/"&F16 -> 5/5 | I17: =G17/2^FLOOR(LOG(G17,2),1) -> 1 | J17: =INDEX($O$4:$O$10,MATCH(ROUND(I17,6),$N$4:$N$10,0)) -> unison / octave(s) | K17: =IF(F17=1,"1:1",F17&":"&(F17-1)) -> 5:4 | L17: =ROUND(G17*INDEX($G$2:$G$52,51-A17+1),9) -> 1 | O17: 4:3 | Q17: =COUNTIF($K$2:$K$26,O17) -> 4
A18: =A17+1 -> 16 | B18: =MOD(4*A18^2,10) -> 4 | C18: =(26*B18-5*B18^2)/24 -> 1 | D18: =(A18^2+4*C18)/5 -> 52 | E18: =MOD(D18,5) -> 2 | F18: =1+MOD(D18-1,5) -> 2 | G18: =F18/F17 -> 0.4 | H18: =F18&"/"&F17 -> 2/5 | I18: =G18/2^FLOOR(LOG(G18,2),1) -> 1.6 | J18: =INDEX($O$4:$O$10,MATCH(ROUND(I18,6),$N$4:$N$10,0)) -> minor sixth | K18: =IF(F18=1,"1:1",F18&":"&(F18-1)) -> 2:1 | L18: =ROUND(G18*INDEX($G$2:$G$52,51-A18+1),9) -> 1 | O18: 5:4 | Q18: =COUNTIF($K$2:$K$26,O18) -> 9
A19: =A18+1 -> 17 | B19: =MOD(4*A19^2,10) -> 6 | C19: =(26*B19-5*B19^2)/24 -> -1 | D19: =(A19^2+4*C19)/5 -> 57 | E19: =MOD(D19,5) -> 2 | F19: =1+MOD(D19-1,5) -> 2 | G19: =F19/F18 -> 1 | H19: =F19&"/"&F18 -> 2/2 | I19: =G19/2^FLOOR(LOG(G19,2),1) -> 1 | J19: =INDEX($O$4:$O$10,MATCH(ROUND(I19,6),$N$4:$N$10,0)) -> unison / octave(s) | K19: =IF(F19=1,"1:1",F19&":"&(F19-1)) -> 2:1 | L19: =ROUND(G19*INDEX($G$2:$G$52,51-A19+1),9) -> 1
A20: =A19+1 -> 18 | B20: =MOD(4*A20^2,10) -> 6 | C20: =(26*B20-5*B20^2)/24 -> -1 | D20: =(A20^2+4*C20)/5 -> 64 | E20: =MOD(D20,5) -> 4 | F20: =1+MOD(D20-1,5) -> 4 | G20: =F20/F19 -> 2 | H20: =F20&"/"&F19 -> 4/2 | I20: =G20/2^FLOOR(LOG(G20,2),1) -> 1 | J20: =INDEX($O$4:$O$10,MATCH(ROUND(I20,6),$N$4:$N$10,0)) -> unison / octave(s) | K20: =IF(F20=1,"1:1",F20&":"&(F20-1)) -> 4:3 | L20: =ROUND(G20*INDEX($G$2:$G$52,51-A20+1),9) -> 1 | N20: Product of the 25 steps (n = 1–25) | Q20: =PRODUCT(G3:G27) -> 1
A21: =A20+1 -> 19 | B21: =MOD(4*A21^2,10) -> 4 | C21: =(26*B21-5*B21^2)/24 -> 1 | D21: =(A21^2+4*C21)/5 -> 73 | E21: =MOD(D21,5) -> 3 | F21: =1+MOD(D21-1,5) -> 3 | G21: =F21/F20 -> 0.75 | H21: =F21&"/"&F20 -> 3/4 | I21: =G21/2^FLOOR(LOG(G21,2),1) -> 1.5 | J21: =INDEX($O$4:$O$10,MATCH(ROUND(I21,6),$N$4:$N$10,0)) -> fifth | K21: =IF(F21=1,"1:1",F21&":"&(F21-1)) -> 3:2 | L21: =ROUND(G21*INDEX($G$2:$G$52,51-A21+1),9) -> 1
A22: =A21+1 -> 20 | B22: =MOD(4*A22^2,10) -> 0 | C22: =(26*B22-5*B22^2)/24 -> 0 | D22: =(A22^2+4*C22)/5 -> 80 | E22: =MOD(D22,5) -> 0 | F22: =1+MOD(D22-1,5) -> 5 | G22: =F22/F21 -> 1.6666667 | H22: =F22&"/"&F21 -> 5/3 | I22: =G22/2^FLOOR(LOG(G22,2),1) -> 1.6666667 | J22: =INDEX($O$4:$O$10,MATCH(ROUND(I22,6),$N$4:$N$10,0)) -> major sixth | K22: =IF(F22=1,"1:1",F22&":"&(F22-1)) -> 5:4 | L22: =ROUND(G22*INDEX($G$2:$G$52,51-A22+1),9) -> 1
A23: =A22+1 -> 21 | B23: =MOD(4*A23^2,10) -> 4 | C23: =(26*B23-5*B23^2)/24 -> 1 | D23: =(A23^2+4*C23)/5 -> 89 | E23: =MOD(D23,5) -> 4 | F23: =1+MOD(D23-1,5) -> 4 | G23: =F23/F22 -> 0.8 | H23: =F23&"/"&F22 -> 4/5 | I23: =G23/2^FLOOR(LOG(G23,2),1) -> 1.6 | J23: =INDEX($O$4:$O$10,MATCH(ROUND(I23,6),$N$4:$N$10,0)) -> minor sixth | K23: =IF(F23=1,"1:1",F23&":"&(F23-1)) -> 4:3 | L23: =ROUND(G23*INDEX($G$2:$G$52,51-A23+1),9) -> 1 | N23: Notes
A24: =A23+1 -> 22 | B24: =MOD(4*A24^2,10) -> 6 | C24: =(26*B24-5*B24^2)/24 -> -1 | D24: =(A24^2+4*C24)/5 -> 96 | E24: =MOD(D24,5) -> 1 | F24: =1+MOD(D24-1,5) -> 1 | G24: =F24/F23 -> 0.25 | H24: =F24&"/"&F23 -> 1/4 | I24: =G24/2^FLOOR(LOG(G24,2),1) -> 1 | J24: =INDEX($O$4:$O$10,MATCH(ROUND(I24,6),$N$4:$N$10,0)) -> unison / octave(s) | K24: =IF(F24=1,"1:1",F24&":"&(F24-1)) -> 1:1 | L24: =ROUND(G24*INDEX($G$2:$G$52,51-A24+1),9) -> 1 | N24: i (no 0): Lluis Garcia Torcal's reading of mod 5 as groups whose members are 1–5 (5 is the fifth member, not 0); written 1 + MOD(𝔓 − 1; 5).
A25: =A24+1 -> 23 | B25: =MOD(4*A25^2,10) -> 6 | C25: =(26*B25-5*B25^2)/24 -> -1 | D25: =(A25^2+4*C25)/5 -> 105 | E25: =MOD(D25,5) -> 0 | F25: =1+MOD(D25-1,5) -> 5 | G25: =F25/F24 -> 5 | H25: =F25&"/"&F24 -> 5/1 | I25: =G25/2^FLOOR(LOG(G25,2),1) -> 1.25 | J25: =INDEX($O$4:$O$10,MATCH(ROUND(I25,6),$N$4:$N$10,0)) -> major third | K25: =IF(F25=1,"1:1",F25&":"&(F25-1)) -> 5:4 | L25: =ROUND(G25*INDEX($G$2:$G$52,51-A25+1),9) -> 1 | N25: With it every step i/i−1 is defined (the usual MOD would give 0 at every silence).
A26: =A25+1 -> 24 | B26: =MOD(4*A26^2,10) -> 4 | C26: =(26*B26-5*B26^2)/24 -> 1 | D26: =(A26^2+4*C26)/5 -> 116 | E26: =MOD(D26,5) -> 1 | F26: =1+MOD(D26-1,5) -> 1 | G26: =F26/F25 -> 0.2 | H26: =F26&"/"&F25 -> 1/5 | I26: =G26/2^FLOOR(LOG(G26,2),1) -> 1.6 | J26: =INDEX($O$4:$O$10,MATCH(ROUND(I26,6),$N$4:$N$10,0)) -> minor sixth | K26: =IF(F26=1,"1:1",F26&":"&(F26-1)) -> 1:1 | L26: =ROUND(G26*INDEX($G$2:$G$52,51-A26+1),9) -> 1 | N26: The note at step n is i(n) times a fundamental: the cycle plays only the harmonics 1–5 (natural trumpet); each step is a leap between two of them.
A27: =A26+1 -> 25 | B27: =MOD(4*A27^2,10) -> 0 | C27: =(26*B27-5*B27^2)/24 -> 0 | D27: =(A27^2+4*C27)/5 -> 125 | E27: =MOD(D27,5) -> 0 | F27: =1+MOD(D27-1,5) -> 5 | G27: =F27/F26 -> 5 | H27: =F27&"/"&F26 -> 5/1 | I27: =G27/2^FLOOR(LOG(G27,2),1) -> 1.25 | J27: =INDEX($O$4:$O$10,MATCH(ROUND(I27,6),$N$4:$N$10,0)) -> major third | K27: =IF(F27=1,"1:1",F27&":"&(F27-1)) -> 5:4 | L27: =ROUND(G27*INDEX($G$2:$G$52,51-A27+1),9) -> 1 | N27: Product of the 25 steps = 1: the melody comes home every period. Last column: step(n) × step(51 − n) = 1: the second half of the palindrome makes the leaps of the first half in reverse order and the other way up (the melody is its own retrograde).
A28: =A27+1 -> 26 | B28: =MOD(4*A28^2,10) -> 4 | C28: =(26*B28-5*B28^2)/24 -> 1 | D28: =(A28^2+4*C28)/5 -> 136 | E28: =MOD(D28,5) -> 1 | F28: =1+MOD(D28-1,5) -> 1 | G28: =F28/F27 -> 0.2 | H28: =F28&"/"&F27 -> 1/5 | I28: =G28/2^FLOOR(LOG(G28,2),1) -> 1.6 | J28: =INDEX($O$4:$O$10,MATCH(ROUND(I28,6),$N$4:$N$10,0)) -> minor sixth | K28: =IF(F28=1,"1:1",F28&":"&(F28-1)) -> 1:1 | L28: =ROUND(G28*INDEX($G$2:$G$52,51-A28+1),9) -> 1 | N28: Any ratio of two numbers from 1 to 5 is consonant (Zarlino's senario); the cycle chooses which ones, how often and in what order.
A29: =A28+1 -> 27 | B29: =MOD(4*A29^2,10) -> 6 | C29: =(26*B29-5*B29^2)/24 -> -1 | D29: =(A29^2+4*C29)/5 -> 145 | E29: =MOD(D29,5) -> 0 | F29: =1+MOD(D29-1,5) -> 5 | G29: =F29/F28 -> 5 | H29: =F29&"/"&F28 -> 5/1 | I29: =G29/2^FLOOR(LOG(G29,2),1) -> 1.25 | J29: =INDEX($O$4:$O$10,MATCH(ROUND(I29,6),$N$4:$N$10,0)) -> major third | K29: =IF(F29=1,"1:1",F29&":"&(F29-1)) -> 5:4 | L29: =ROUND(G29*INDEX($G$2:$G$52,51-A29+1),9) -> 1 | N29: Reading A: i:(i−1) with the silences read as 5 gives 5:4, a major third, in place of every silence.
A30: =A29+1 -> 28 | B30: =MOD(4*A30^2,10) -> 6 | C30: =(26*B30-5*B30^2)/24 -> -1 | D30: =(A30^2+4*C30)/5 -> 156 | E30: =MOD(D30,5) -> 1 | F30: =1+MOD(D30-1,5) -> 1 | G30: =F30/F29 -> 0.2 | H30: =F30&"/"&F29 -> 1/5 | I30: =G30/2^FLOOR(LOG(G30,2),1) -> 1.6 | J30: =INDEX($O$4:$O$10,MATCH(ROUND(I30,6),$N$4:$N$10,0)) -> minor sixth | K30: =IF(F30=1,"1:1",F30&":"&(F30-1)) -> 1:1 | L30: =ROUND(G30*INDEX($G$2:$G$52,51-A30+1),9) -> 1 | N30: Rows n = 0, 25, 50 (the silent axis and its ends) are shaded.
A31: =A30+1 -> 29 | B31: =MOD(4*A31^2,10) -> 4 | C31: =(26*B31-5*B31^2)/24 -> 1 | D31: =(A31^2+4*C31)/5 -> 169 | E31: =MOD(D31,5) -> 4 | F31: =1+MOD(D31-1,5) -> 4 | G31: =F31/F30 -> 4 | H31: =F31&"/"&F30 -> 4/1 | I31: =G31/2^FLOOR(LOG(G31,2),1) -> 1 | J31: =INDEX($O$4:$O$10,MATCH(ROUND(I31,6),$N$4:$N$10,0)) -> unison / octave(s) | K31: =IF(F31=1,"1:1",F31&":"&(F31-1)) -> 4:3 | L31: =ROUND(G31*INDEX($G$2:$G$52,51-A31+1),9) -> 1
A32: =A31+1 -> 30 | B32: =MOD(4*A32^2,10) -> 0 | C32: =(26*B32-5*B32^2)/24 -> 0 | D32: =(A32^2+4*C32)/5 -> 180 | E32: =MOD(D32,5) -> 0 | F32: =1+MOD(D32-1,5) -> 5 | G32: =F32/F31 -> 1.25 | H32: =F32&"/"&F31 -> 5/4 | I32: =G32/2^FLOOR(LOG(G32,2),1) -> 1.25 | J32: =INDEX($O$4:$O$10,MATCH(ROUND(I32,6),$N$4:$N$10,0)) -> major third | K32: =IF(F32=1,"1:1",F32&":"&(F32-1)) -> 5:4 | L32: =ROUND(G32*INDEX($G$2:$G$52,51-A32+1),9) -> 1
A33: =A32+1 -> 31 | B33: =MOD(4*A33^2,10) -> 4 | C33: =(26*B33-5*B33^2)/24 -> 1 | D33: =(A33^2+4*C33)/5 -> 193 | E33: =MOD(D33,5) -> 3 | F33: =1+MOD(D33-1,5) -> 3 | G33: =F33/F32 -> 0.6 | H33: =F33&"/"&F32 -> 3/5 | I33: =G33/2^FLOOR(LOG(G33,2),1) -> 1.2 | J33: =INDEX($O$4:$O$10,MATCH(ROUND(I33,6),$N$4:$N$10,0)) -> minor third | K33: =IF(F33=1,"1:1",F33&":"&(F33-1)) -> 3:2 | L33: =ROUND(G33*INDEX($G$2:$G$52,51-A33+1),9) -> 1
A34: =A33+1 -> 32 | B34: =MOD(4*A34^2,10) -> 6 | C34: =(26*B34-5*B34^2)/24 -> -1 | D34: =(A34^2+4*C34)/5 -> 204 | E34: =MOD(D34,5) -> 4 | F34: =1+MOD(D34-1,5) -> 4 | G34: =F34/F33 -> 1.3333333 | H34: =F34&"/"&F33 -> 4/3 | I34: =G34/2^FLOOR(LOG(G34,2),1) -> 1.3333333 | J34: =INDEX($O$4:$O$10,MATCH(ROUND(I34,6),$N$4:$N$10,0)) -> fourth | K34: =IF(F34=1,"1:1",F34&":"&(F34-1)) -> 4:3 | L34: =ROUND(G34*INDEX($G$2:$G$52,51-A34+1),9) -> 1
A35: =A34+1 -> 33 | B35: =MOD(4*A35^2,10) -> 6 | C35: =(26*B35-5*B35^2)/24 -> -1 | D35: =(A35^2+4*C35)/5 -> 217 | E35: =MOD(D35,5) -> 2 | F35: =1+MOD(D35-1,5) -> 2 | G35: =F35/F34 -> 0.5 | H35: =F35&"/"&F34 -> 2/4 | I35: =G35/2^FLOOR(LOG(G35,2),1) -> 1 | J35: =INDEX($O$4:$O$10,MATCH(ROUND(I35,6),$N$4:$N$10,0)) -> unison / octave(s) | K35: =IF(F35=1,"1:1",F35&":"&(F35-1)) -> 2:1 | L35: =ROUND(G35*INDEX($G$2:$G$52,51-A35+1),9) -> 1
